Workbook

Sheet README
B2: Healthcare Data Cleaning & Understanding
B3: Internship Project — Data Exploration, Cleaning & Basic Analysis
B5: Objective
B6: This workbook explores a healthcare dataset containing patient information (age, gender, disease, medication and dosage), identifies the type of each column, cleans missing values and duplicate records, and produces basic analysis such as patient count, common diseases and average age.
B8: Dataset
B9: A synthetic but realistic healthcare dataset was generated for this exercise, deliberately including the kinds of problems real hospital data usually has: missing values, inconsistent text formatting (e.g. 'Male' / 'MALE' / 'm'), invalid entries (e.g. impossible ages), and exact duplicate records.
B11: How this workbook is organized
B12: • Column Dictionary — Lists every column, its data type (categorical / numerical / date / identifier) and a description — answers 'what kind of data is in each column'.
B13: • Raw Data — The original, uncleaned dataset exactly as collected, including a formula-driven Duplicate_Flag column that detects exact duplicate rows.
B14: • Data Quality Report — Missing-value counts per column, duplicate/invalid entry counts, and a written log of every cleaning rule applied and why.
B15: • Cleaned Data — The final cleaned dataset after removing duplicates, fixing invalid values and standardizing text — this is the dataset used for analysis.
B16: • Analysis Summary — Basic analysis requested by the task: total patient count, average/median age, gender distribution, most common diseases and most prescribed medications, with charts.
... B28: Every count and average in this workbook is a live Excel formula (COUNTIF, AVERAGE, AVERAGEIFS, etc.) referencing the Cleaned Data sheet — not a typed-in number — so the figures recalculate automatically if the underlying data changes.

Sheet Column Dictionary
B2: Column Dictionary
B3: What kind of data each column holds
B5: Column Name | C5: Data Type | D5: Category | E5: Description | F5: Example Value
B6: PatientID | C6: Text (unique code) | D6: Identifier | E6: Unique ID assigned to each patient record | F6: PT0001
B7: Name | C7: Text | D7: Categorical (nominal) | E7: Patient's full name | F7: Priya Sharma
B8: Age | C8: Numeric (integer) | D8: Numerical (discrete) | E8: Patient's age in years | F8: 45
B9: Gender | C9: Text | D9: Categorical (nominal) | E9: Patient's gender | F9: Male
B10: Disease | C10: Text | D10: Categorical (nominal) | E10: Diagnosed medical condition | F10: Hypertension
B11: Medication | C11: Text | D11: Categorical (nominal) | E11: Medication prescribed for the disease | F11: Amlodipine
B12: Dosage_mg | C12: Numeric (continuous) | D12: Numerical | E12: Prescribed dosage, in milligrams | F12: 10
B13: Admission_Date | C13: Date | D13: Date / Time | E13: Date the patient was admitted | F13: 2025-03-14

Sheet Raw Data
A1: PatientID | B1: Name | C1: Age | D1: Gender | E1: Disease | F1: Medication | G1: Dosage_mg | H1: Admission_Date | I1: RowKey (helper) | J1: Duplicate_Flag
A2: PT0137 | B2: Rohit Nair | C2: 58 | D2: M | E2: Arthritis | F2: Ibuprofen | G2: 320 | H2: 45731 | I2: =A2&"|"&B2&"|"&C2&"|"&D2&"|"&E2&"|"&F2&"|"&G2&"|"&H2 -> PT0137|Rohit Nair|58|M|Arthritis|Ibuprofen|320|45731 | J2: =IF(COUNTIF($I$2:I2,I2)>1,"Duplicate","Unique") -> Unique
A3: PT0035 | B3: Alok Mishra | C3: 55 | D3: Male | E3: Diabetes | F3: Metformin | G3: 755 | H3: 45596 | I3: =A3&"|"&B3&"|"&C3&"|"&D3&"|"&E3&"|"&F3&"|"&G3&"|"&H3 -> PT0035|Alok Mishra|55|Male|Diabetes| Metformin |755|45596 | J3: =IF(COUNTIF($I$2:I3,I3)>1,"Duplicate","Unique") -> Unique
A4: PT0214 | B4: Vinod Chauhan | C4: 50 | D4: Male | E4: Depression | F4: SERTRALINE | G4: 75 | H4: 45690 | I4: =A4&"|"&B4&"|"&C4&"|"&D4&"|"&E4&"|"&F4&"|"&G4&"|"&H4 -> PT0214|Vinod Chauhan|50| Male| Depression |SERTRALINE|75|45690 | J4: =IF(COUNTIF($I$2:I4,I4)>1,"Duplicate","Unique") -> Unique
A5: PT0088 | B5: Payal Shukla | C5: 58 | D5: female | E5: Diabetes | G5: 765 | H5: 45794 | I5: =A5&"|"&B5&"|"&C5&"|"&D5&"|"&E5&"|"&F5&"|"&G5&"|"&H5 -> PT0088|Payal Shukla|58|female|Diabetes ||765|45794 | J5: =IF(COUNTIF($I$2:I5,I5)>1,"Duplicate","Unique") -> Unique
A6: PT0198 | B6: Sanjay Shukla | C6: 39 | D6: MALE | E6: Flu | F6: Paracetamol | G6: 550 | H6: 45697 | I6: =A6&"|"&B6&"|"&C6&"|"&D6&"|"&E6&"|"&F6&"|"&G6&"|"&H6 -> PT0198|Sanjay Shukla|39|MALE| Flu |Paracetamol |550|45697 | J6: =IF(COUNTIF($I$2:I6,I6)>1,"Duplicate","Unique") -> Unique
A7: PT0002 | B7: Priya Gupta | C7: 55 | D7: Female | E7: Diabetes | F7: metformin | G7: 820 | H7: 46152 | I7: =A7&"|"&B7&"|"&C7&"|"&D7&"|"&E7&"|"&F7&"|"&G7&"|"&H7 -> PT0002|Priya Gupta|55|Female| Diabetes |metformin|820|46152 | J7: =IF(COUNTIF($I$2:I7,I7)>1,"Duplicate","Unique") -> Unique
A8: PT0142 | B8: Ritu Pandey | C8: 74 | D8: F | E8: HYPERTENSION | F8: amlodipine | G8: 10 | H8: 46258 | I8: =A8&"|"&B8&"|"&C8&"|"&D8&"|"&E8&"|"&F8&"|"&G8&"|"&H8 -> PT0142|Ritu Pandey|74|F|HYPERTENSION|amlodipine|10|46258 | J8: =IF(COUNTIF($I$2:I8,I8)>1,"Duplicate","Unique") -> Unique
A9: PT0150 | B9: Suresh Joshi | C9: 45 | E9: hypertension | F9: AMLODIPINE | G9: 10 | H9: 45565 | I9: =A9&"|"&B9&"|"&C9&"|"&D9&"|"&E9&"|"&F9&"|"&G9&"|"&H9 -> PT0150|Suresh Joshi|45||hypertension|AMLODIPINE|10|45565 | J9: =IF(COUNTIF($I$2:I9,I9)>1,"Duplicate","Unique") -> Unique
A10: PT0074 | B10: Sarita Reddy | C10: 23 | D10: Female | E10: Asthma | F10: SALBUTAMOL | G10: 185 | H10: 45791 | I10: =A10&"|"&B10&"|"&C10&"|"&D10&"|"&E10&"|"&F10&"|"&G10&"|"&H10 -> PT0074|Sarita Reddy|23| Female| Asthma |SALBUTAMOL|185|45791 | J10: =IF(COUNTIF($I$2:I10,I10)>1,"Duplicate","Unique") -> Unique
A11: PT0095 | B11: Preeti Agarwal | C11: 59 | D11: f | E11: hypertension | F11: Amlodipine | G11: 5 | H11: 45891 | I11: =A11&"|"&B11&"|"&C11&"|"&D11&"|"&E11&"|"&F11&"|"&G11&"|"&H11 -> PT0095|Preeti Agarwal|59|f|hypertension| Amlodipine |5|45891 | J11: =IF(COUNTIF($I$2:I11,I11)>1,"Duplicate","Unique") -> Unique
A12: PT0011 | B12: Gopal Rao | C12: 48 | D12: male | E12: bronchitis | F12: Azithromycin | G12: 265 | H12: 45770 | I12: =A12&"|"&B12&"|"&C12&"|"&D12&"|"&E12&"|"&F12&"|"&G12&"|"&H12 -> PT0011|Gopal Rao|48|male|bronchitis|Azithromycin|265|45770 | J12: =IF(COUNTIF($I$2:I12,I12)>1,"Duplicate","Unique") -> Unique
A13: PT0015 | B13: Arjun Rathore | C13: 57 | D13: Male | F13: salbutamol | H13: 45584 | I13: =A13&"|"&B13&"|"&C13&"|"&D13&"|"&E13&"|"&F13&"|"&G13&"|"&H13 -> PT0015|Arjun Rathore|57|Male||salbutamol||45584 | J13: =IF(COUNTIF($I$2:I13,I13)>1,"Duplicate","Unique") -> Unique
A14: PT0182 | B14: Lata Sharma | C14: 69 | D14: FEMALE | E14: Hypertension | F14: Amlodipine | G14: 10 | H14: 45947 | I14: =A14&"|"&B14&"|"&C14&"|"&D14&"|"&E14&"|"&F14&"|"&G14&"|"&H14 -> PT0182|Lata Sharma|69|FEMALE| Hypertension |Amlodipine|10|45947 | J14: =IF(COUNTIF($I$2:I14,I14)>1,"Duplicate","Unique") -> Unique
A15: PT0203 | B15: Usha Verma | C15: 60 | D15: female | E15: diabetes | F15: Metformin | G15: 585 | H15: 45797 | I15: =A15&"|"&B15&"|"&C15&"|"&D15&"|"&E15&"|"&F15&"|"&G15&"|"&H15 -> PT0203|Usha Verma|60|female|diabetes|Metformin |585|45797 | J15: =IF(COUNTIF($I$2:I15,I15)>1,"Duplicate","Unique") -> Unique
A16: PT0032 | B16: Gopal Singh | C16: 56 | D16: male | E16: hypertension | F16: Amlodipine | G16: 10 | H16: 45647 | I16: =A16&"|"&B16&"|"&C16&"|"&D16&"|"&E16&"|"&F16&"|"&G16&"|"&H16 -> PT0032|Gopal Singh|56|male|hypertension|Amlodipine|10|45647 | J16: =IF(COUNTIF($I$2:I16,I16)>1,"Duplicate","Unique") -> Unique
A17: PT0151 | B17: Swati Verma | C17: 40 | D17: Female | E17: HYPERTENSION | G17: 10 | I17: =A17&"|"&B17&"|"&C17&"|"&D17&"|"&E17&"|"&F17&"|"&G17&"|"&H17 -> PT0151|Swati Verma|40|Female |HYPERTENSION||10| | J17: =IF(COUNTIF($I$2:I17,I17)>1,"Duplicate","Unique") -> Unique
A18: PT0069 | B18: Karan Kumar | C18: 37 | D18: Male | E18: Migraine | F18: Sumatriptan | G18: 75 | H18: 45631 | I18: =A18&"|"&B18&"|"&C18&"|"&D18&"|"&E18&"|"&F18&"|"&G18&"|"&H18 -> PT0069|Karan Kumar|37|Male| Migraine |Sumatriptan |75|45631 | J18: =IF(COUNTIF($I$2:I18,I18)>1,"Duplicate","Unique") -> Unique
A19: PT0144 | B19: Ramesh Reddy | C19: 43 | D19: MALE | E19: THYROID DISORDER | F19: Levothyroxine | G19: 75 | H19: 45638 | I19: =A19&"|"&B19&"|"&C19&"|"&D19&"|"&E19&"|"&F19&"|"&G19&"|"&H19 -> PT0144|Ramesh Reddy|43|MALE|THYROID DISORDER| Levothyroxine |75|45638 | J19: =IF(COUNTIF($I$2:I19,I19)>1,"Duplicate","Unique") -> Unique
A20: PT0108 | B20: Divya Kumar | C20: 59 | D20: FEMALE | E20: Diabetes | F20: Metformin | G20: 970 | H20: 46031 | I20: =A20&"|"&B20&"|"&C20&"|"&D20&"|"&E20&"|"&F20&"|"&G20&"|"&H20 -> PT0108|Divya Kumar|59|FEMALE| Diabetes |Metformin |970|46031 | J20: =IF(COUNTIF($I$2:I20,I20)>1,"Duplicate","Unique") -> Unique
A21: PT0218 | B21: Swati Choudhary | C21: 31 | D21: female | E21: MIGRAINE | F21: Sumatriptan | G21: 75 | H21: 46155 | I21: =A21&"|"&B21&"|"&C21&"|"&D21&"|"&E21&"|"&F21&"|"&G21&"|"&H21 -> PT0218|Swati Choudhary|31|female|MIGRAINE|Sumatriptan|75|46155 | J21: =IF(COUNTIF($I$2:I21,I21)>1,"Duplicate","Unique") -> Unique
A22: PT0162 | B22: Pooja Rao | C22: 52 | D22: FEMALE | E22: Depression | F22: Sertraline | G22: 80 | H22: 46079 | I22: =A22&"|"&B22&"|"&C22&"|"&D22&"|"&E22&"|"&F22&"|"&G22&"|"&H22 -> PT0162|Pooja Rao|52|FEMALE|Depression| Sertraline |80|46079 | J22: =IF(COUNTIF($I$2:I22,I22)>1,"Duplicate","Unique") -> Unique
A23: PT0202 | B23: Suman Choudhary | C23: 50 | D23: f | E23: Asthma | F23: SALBUTAMOL | G23: 145 | H23: 45582 | I23: =A23&"|"&B23&"|"&C23&"|"&D23&"|"&E23&"|"&F23&"|"&G23&"|"&H23 -> PT0202|Suman Choudhary|50|f| Asthma |SALBUTAMOL|145|45582 | J23: =IF(COUNTIF($I$2:I23,I23)>1,"Duplicate","Unique") -> Unique
A24: PT0055 | B24: Karan Kumar | C24: 48 | D24: Male | E24: Anemia | F24: Ferrous Sulfate | G24: 250 | H24: 45957 | I24: =A24&"|"&B24&"|"&C24&"|"&D24&"|"&E24&"|"&F24&"|"&G24&"|"&H24 -> PT0055|Karan Kumar|48| Male| Anemia |Ferrous Sulfate|250|45957 | J24: =IF(COUNTIF($I$2:I24,I24)>1,"Duplicate","Unique") -> Unique
A25: PT0160 | B25: Dinesh Yadav | C25: 33 | D25: M | E25: MIGRAINE | F25: sumatriptan | G25: 30 | H25: 45852 | I25: =A25&"|"&B25&"|"&C25&"|"&D25&"|"&E25&"|"&F25&"|"&G25&"|"&H25 -> PT0160|Dinesh Yadav|33|M|MIGRAINE|sumatriptan|30|45852 | J25: =IF(COUNTIF($I$2:I25,I25)>1,"Duplicate","Unique") -> Unique
A26: PT0037 | B26: Sarita Rao | C26: 34 | D26: Female | E26: Diabetes | F26: Metformin | G26: 635 | H26: 45595 | I26: =A26&"|"&B26&"|"&C26&"|"&D26&"|"&E26&"|"&F26&"|"&G26&"|"&H26 -> PT0037|Sarita Rao|34| Female|Diabetes |Metformin |635|45595 | J26: =IF(COUNTIF($I$2:I26,I26)>1,"Duplicate","Unique") -> Unique
A27: PT0084 | B27: Nisha Nair | C27: 38 | D27: F | E27: Hypertension | F27: Amlodipine | G27: 10 | H27: 46220 | I27: =A27&"|"&B27&"|"&C27&"|"&D27&"|"&E27&"|"&F27&"|"&G27&"|"&H27 -> PT0084|Nisha Nair|38|F|Hypertension |Amlodipine|10|46220 | J27: =IF(COUNTIF($I$2:I27,I27)>1,"Duplicate","Unique") -> Unique
A28: PT0057 | B28: Ritu Verma | C28: 53 | D28: Female | E28: OBESITY | F28: Orlistat | G28: 95 | H28: 45894 | I28: =A28&"|"&B28&"|"&C28&"|"&D28&"|"&E28&"|"&F28&"|"&G28&"|"&H28 -> PT0057|Ritu Verma|53|Female |OBESITY|Orlistat|95|45894 | J28: =IF(COUNTIF($I$2:I28,I28)>1,"Duplicate","Unique") -> Unique
A29: PT0225 | B29: Arjun Yadav | C29: 10 | D29: Male | E29: Diabetes | F29: Metformin | G29: 740 | H29: 46194 | I29: =A29&"|"&B29&"|"&C29&"|"&D29&"|"&E29&"|"&F29&"|"&G29&"|"&H29 -> PT0225|Arjun Yadav|10| Male| Diabetes | Metformin |740|46194 | J29: =IF(COUNTIF($I$2:I29,I29)>1,"Duplicate","Unique") -> Unique
... A34: PT0178 | B34: Neha Singh | C34: 46 | D34: female | E34: Migraine | F34: Sumatriptan | G34: 25 | H34: 45670 | I34: =A34&"|"&B34&"|"&C34&"|"&D34&"|"&E34&"|"&F34&"|"&G34&"|"&H34 -> PT0178|Neha Singh|46|female| Migraine |Sumatriptan |25|45670 | J34: =IF(COUNTIF($I$2:I34,I34)>1,"Duplicate","Unique") -> Unique
A35: PT0219 | B35: Pooja Verma | C35: 14 | D35: Female | E35: Obesity | G35: 115 | H35: 45622 | I35: =A35&"|"&B35&"|"&C35&"|"&D35&"|"&E35&"|"&F35&"|"&G35&"|"&H35 -> PT0219|Pooja Verma|14| Female|Obesity ||115|45622 | J35: =IF(COUNTIF($I$2:I35,I35)>1,"Duplicate","Unique") -> Unique
A36: PT0100 | B36: Vijay Tiwari | C36: 52 | D36: Male | E36: Allergy | F36: Cetirizine | G36: 5 | H36: 46011 | I36: =A36&"|"&B36&"|"&C36&"|"&D36&"|"&E36&"|"&F36&"|"&G36&"|"&H36 -> PT0100|Vijay Tiwari|52| Male|Allergy|Cetirizine |5|46011 | J36: =IF(COUNTIF($I$2:I36,I36)>1,"Duplicate","Unique") -> Unique
A37: PT0070 | B37: Dinesh Mishra | C37: 33 | D37: Male | F37: Sumatriptan | G37: 60 | H37: 45739 | I37: =A37&"|"&B37&"|"&C37&"|"&D37&"|"&E37&"|"&F37&"|"&G37&"|"&H37 -> PT0070|Dinesh Mishra|33|Male ||Sumatriptan |60|45739 | J37: =IF(COUNTIF($I$2:I37,I37)>1,"Duplicate","Unique") -> Unique
A38: PT0209 | B38: Kavita Mishra | C38: 999 | D38: Female | E38: Hypertension | F38: Amlodipine | G38: 10 | H38: 45883 | I38: =A38&"|"&B38&"|"&C38&"|"&D38&"|"&E38&"|"&F38&"|"&G38&"|"&H38 -> PT0209|Kavita Mishra|999|Female|Hypertension |Amlodipine |10|45883 | J38: =IF(COUNTIF($I$2:I38,I38)>1,"Duplicate","Unique") -> Unique
A39: PT0040 | B39: Mahesh Mishra | C39: 83 | D39: MALE | E39: FLU | F39: Paracetamol | G39: 650 | H39: 46119 | I39: =A39&"|"&B39&"|"&C39&"|"&D39&"|"&E39&"|"&F39&"|"&G39&"|"&H39 -> PT0040|Mahesh Mishra|83|MALE|FLU|Paracetamol |650|46119 | J39: =IF(COUNTIF($I$2:I39,I39)>1,"Duplicate","Unique") -> Unique
A40: PT0167 | B40: Rekha Nair | C40: 82 | D40: FEMALE | E40: Arthritis | F40: Ibuprofen | G40: 395 | H40: 45762 | I40: =A40&"|"&B40&"|"&C40&"|"&D40&"|"&E40&"|"&F40&"|"&G40&"|"&H40 -> PT0167|Rekha Nair|82|FEMALE|Arthritis |Ibuprofen |395|45762 | J40: =IF(COUNTIF($I$2:I40,I40)>1,"Duplicate","Unique") -> Unique
A41: PT0077 | B41: Ashok Joshi | D41: m | E41: Asthma | F41: salbutamol | G41: 140 | H41: 45789 | I41: =A41&"|"&B41&"|"&C41&"|"&D41&"|"&E41&"|"&F41&"|"&G41&"|"&H41 -> PT0077|Ashok Joshi||m| Asthma |salbutamol|140|45789 | J41: =IF(COUNTIF($I$2:I41,I41)>1,"Duplicate","Unique") -> Unique
A42: PT0199 | B42: Vandana Chauhan | C42: 49 | D42: F | E42: hypertension | F42: AMLODIPINE | G42: 5 | H42: 45695 | I42: =A42&"|"&B42&"|"&C42&"|"&D42&"|"&E42&"|"&F42&"|"&G42&"|"&H42 -> PT0199|Vandana Chauhan|49|F|hypertension|AMLODIPINE|5|45695 | J42: =IF(COUNTIF($I$2:I42,I42)>1,"Duplicate","Unique") -> Unique
A43: PT0091 | B43: Vinod Yadav | C43: 46 | D43: Male | E43: HYPERTENSION | F43: Amlodipine | H43: 46012 | I43: =A43&"|"&B43&"|"&C43&"|"&D43&"|"&E43&"|"&F43&"|"&G43&"|"&H43 -> PT0091|Vinod Yadav|46| Male|HYPERTENSION| Amlodipine ||46012 | J43: =IF(COUNTIF($I$2:I43,I43)>1,"Duplicate","Unique") -> Unique
A44: PT0161 | B44: Amit Choudhary | C44: 39 | D44: Male | E44: allergy | F44: Cetirizine | G44: 10 | H44: 45961 | I44: =A44&"|"&B44&"|"&C44&"|"&D44&"|"&E44&"|"&F44&"|"&G44&"|"&H44 -> PT0161|Amit Choudhary|39| Male|allergy| Cetirizine |10|45961 | J44: =IF(COUNTIF($I$2:I44,I44)>1,"Duplicate","Unique") -> Unique
...

Sheet Data Quality Report
B2: Data Quality Report
B3: Issues found in the raw data, and how they were resolved
B5: 1. Raw Dataset Overview
B6: Total raw rows collected | C6: =COUNTA('Raw Data'!A2:A251) -> 250
B7: Exact duplicate rows found | C7: =COUNTIF('Raw Data'!J2:J251,"Duplicate") -> 20
B8: Invalid ages found (≤0 or >110) | C8: =COUNTIF('Raw Data'!C2:C251,"<=0")+COUNTIF('Raw Data'!C2:C251,">110") -> 4
B10: 2. Missing Values by Column (Raw Data)
B11: Column | C11: Missing Count | D11: % of Raw Rows
B12: Name | C12: =COUNTBLANK('Raw Data'!B2:B251) -> 3 | D12: =C12/250 -> 0.012
B13: Age | C13: =COUNTBLANK('Raw Data'!C2:C251) -> 10 | D13: =C13/250 -> 0.04
B14: Gender | C14: =COUNTBLANK('Raw Data'!D2:D251) -> 7 | D14: =C14/250 -> 0.028
B15: Disease | C15: =COUNTBLANK('Raw Data'!E2:E251) -> 10 | D15: =C15/250 -> 0.04
B16: Medication | C16: =COUNTBLANK('Raw Data'!F2:F251) -> 12 | D16: =C16/250 -> 0.048
B17: Dosage_mg | C17: =COUNTBLANK('Raw Data'!G2:G251) -> 8 | D17: =C17/250 -> 0.032
B18: Admission_Date | C18: =COUNTBLANK('Raw Data'!H2:H251) -> 8 | D18: =C18/250 -> 0.032
B20: 3. Cleaning Actions Taken
B21: • Removed exact duplicate rows (identical PatientID and every field) — kept the first occurrence. Detected using the Duplicate_Flag helper column on the Raw Data sheet.
B22: • Trimmed extra whitespace and standardized text case for Gender ('MALE'/'m'/' Male ' → 'Male'), Disease and Medication (title case).
B23: • Treated ages ≤ 0 or > 110 as data-entry errors, reset to missing, then imputed with the dataset median age.
B24: • Imputed remaining missing Age values with the overall median age.
B25: • Imputed missing Dosage_mg with the median dosage recorded for that same medication (overall median used as a fallback).
B26: • Missing Gender recoded as 'Unknown'; missing Disease/Medication recoded as 'Not Specified' — kept instead of deleting the row, so the rest of the patient's data is not lost.
B27: • Missing Admission_Date left blank (not imputed) — a fabricated date would be misleading.
B29: 4. Result
B30: Rows in cleaned dataset | C30: =COUNTA('Cleaned Data'!A2:A231) -> 230

Sheet Cleaned Data
A1: PatientID | B1: Name | C1: Age | D1: Gender | E1: Disease | F1: Medication | G1: Dosage_mg | H1: Admission_Date
A2: PT0137 | B2: Rohit Nair | C2: 58 | D2: Male | E2: Arthritis | F2: Ibuprofen | G2: 320 | H2: 45731
A3: PT0035 | B3: Alok Mishra | C3: 55 | D3: Male | E3: Diabetes | F3: Metformin | G3: 755 | H3: 45596
A4: PT0214 | B4: Vinod Chauhan | C4: 50 | D4: Male | E4: Depression | F4: Sertraline | G4: 75 | H4: 45690
A5: PT0088 | B5: Payal Shukla | C5: 58 | D5: Female | E5: Diabetes | F5: Not Specified | G5: 765 | H5: 45794
A6: PT0198 | B6: Sanjay Shukla | C6: 39 | D6: Male | E6: Flu | F6: Paracetamol | G6: 550 | H6: 45697
A7: PT0002 | B7: Priya Gupta | C7: 55 | D7: Female | E7: Diabetes | F7: Metformin | G7: 820 | H7: 46152
A8: PT0142 | B8: Ritu Pandey | C8: 74 | D8: Female | E8: Hypertension | F8: Amlodipine | G8: 10 | H8: 46258
A9: PT0150 | B9: Suresh Joshi | C9: 45 | D9: Unknown | E9: Hypertension | F9: Amlodipine | G9: 10 | H9: 45565
A10: PT0074 | B10: Sarita Reddy | C10: 23 | D10: Female | E10: Asthma | F10: Salbutamol | G10: 185 | H10: 45791
A11: PT0095 | B11: Preeti Agarwal | C11: 59 | D11: Female | E11: Hypertension | F11: Amlodipine | G11: 5 | H11: 45891
A12: PT0011 | B12: Gopal Rao | C12: 48 | D12: Male | E12: Bronchitis | F12: Azithromycin | G12: 265 | H12: 45770
A13: PT0015 | B13: Arjun Rathore | C13: 57 | D13: Male | E13: Not Specified | F13: Salbutamol | G13: 145 | H13: 45584
... A16: PT0032 | B16: Gopal Singh | C16: 56 | D16: Male | E16: Hypertension | F16: Amlodipine | G16: 10 | H16: 45647
A17: PT0151 | B17: Swati Verma | C17: 40 | D17: Female | E17: Hypertension | F17: Not Specified | G17: 10
A18: PT0069 | B18: Karan Kumar | C18: 37 | D18: Male | E18: Migraine | F18: Sumatriptan | G18: 75 | H18: 45631
A19: PT0144 | B19: Ramesh Reddy | C19: 43 | D19: Male | E19: Thyroid Disorder | F19: Levothyroxine | G19: 75 | H19: 45638
A20: PT0108 | B20: Divya Kumar | C20: 59 | D20: Female | E20: Diabetes | F20: Metformin | G20: 970 | H20: 46031
A21: PT0218 | B21: Swati Choudhary | C21: 31 | D21: Female | E21: Migraine | F21: Sumatriptan | G21: 75 | H21: 46155
A22: PT0162 | B22: Pooja Rao | C22: 52 | D22: Female | E22: Depression | F22: Sertraline | G22: 80 | H22: 46079
A23: PT0202 | B23: Suman Choudhary | C23: 50 | D23: Female | E23: Asthma | F23: Salbutamol | G23: 145 | H23: 45582
A24: PT0055 | B24: Karan Kumar | C24: 48 | D24: Male | E24: Anemia | F24: Ferrous Sulfate | G24: 250 | H24: 45957
A25: PT0160 | B25: Dinesh Yadav | C25: 33 | D25: Male | E25: Migraine | F25: Sumatriptan | G25: 30 | H25: 45852
A26: PT0037 | B26: Sarita Rao | C26: 34 | D26: Female | E26: Diabetes | F26: Metformin | G26: 635 | H26: 45595
A27: PT0084 | B27: Nisha Nair | C27: 38 | D27: Female | E27: Hypertension | F27: Amlodipine | G27: 10 | H27: 46220
A28: PT0057 | B28: Ritu Verma | C28: 53 | D28: Female | E28: Obesity | F28: Orlistat | G28: 95 | H28: 45894
A29: PT0225 | B29: Arjun Yadav | C29: 10 | D29: Male | E29: Diabetes | F29: Metformin | G29: 740 | H29: 46194
... A43: PT0161 | B43: Amit Choudhary | C43: 39 | D43: Male | E43: Allergy | F43: Cetirizine | G43: 10 | H43: 45961
A44: PT0036 | B44: Priya Shukla | C44: 63 | D44: Female | E44: Diabetes | F44: Metformin | G44: 1000
A45: PT0175 | B45: Gopal Saxena | C45: 51 | D45: Male | E45: Flu | F45: Paracetamol | G45: 520 | H45: 46114
A46: PT0101 | B46: Mahesh Shukla | C46: 34 | D46: Male | E46: Flu | F46: Paracetamol | G46: 575 | H46: 45753
A47: PT0060 | B47: Ashok Chauhan | C47: 42 | D47: Male | E47: Gastritis | F47: Omeprazole | G47: 20 | H47: 45803
A48: PT0073 | B48: Pooja Sharma | C48: 73 | D48: Female | E48: Allergy | F48: Cetirizine | G48: 10 | H48: 45760
A49: PT0063 | B49: Sarita Pandey | C49: 86 | D49: Female | E49: Asthma | F49: Salbutamol | G49: 130 | H49: 45908
A50: PT0105 | B50: Vijay Agarwal | C50: 50 | D50: Male | E50: Diabetes | F50: Metformin | G50: 870 | H50: 45913
A51: PT0009 | B51: Shalini Rathore | C51: 54 | D51: Female | E51: Migraine | F51: Sumatriptan | G51: 35 | H51: 46159
A52: PT0052 | B52: Shweta Choudhary | C52: 73 | D52: Female | E52: Arthritis | F52: Ibuprofen | G52: 335 | H52: 45666
A53: PT0192 | B53: Manju Reddy | C53: 24 | D53: Female | E53: Diabetes | F53: Metformin | G53: 920 | H53: 46029
A54: PT0019 | B54: Suman Pandey | C54: 46 | D54: Female | E54: Anemia | F54: Ferrous Sulfate | G54: 315 | H54: 45805
A55: PT0110 | B55: Suman Sharma | C55: 16 | D55: Female | E55: Anemia | F55: Ferrous Sulfate | G55: 220 | H55: 45816
...

Sheet Analysis Summary
B2: Analysis Summary
B3: Basic analysis of the cleaned dataset (all figures are live formulas)
B5: Overview
B6: Total Patients | C6: =COUNTA('Cleaned Data'!A2:A231) -> 230
B7: Average Age (yrs) | C7: =ROUND(AVERAGE('Cleaned Data'!C2:C231),1) -> 46.4
B8: Median Age (yrs) | C8: =MEDIAN('Cleaned Data'!C2:C231) -> 46
B9: Youngest Patient (yrs) | C9: =MIN('Cleaned Data'!C2:C231) -> 4
B10: Oldest Patient (yrs) | C10: =MAX('Cleaned Data'!C2:C231) -> 95
B11: Average Dosage (mg) | C11: =ROUND(AVERAGE('Cleaned Data'!G2:G231),1) -> 275.3
B13: Gender Distribution
B14: Gender | C14: Patient Count | D14: % of Total
B15: Male | C15: =COUNTIF('Cleaned Data'!D2:D231,"Male") -> 114 | D15: =C15/'Analysis Summary'!$C$6 -> 0.49565217
B16: Female | C16: =COUNTIF('Cleaned Data'!D2:D231,"Female") -> 110 | D16: =C16/'Analysis Summary'!$C$6 -> 0.47826087
B17: Unknown | C17: =COUNTIF('Cleaned Data'!D2:D231,"Unknown") -> 6 | D17: =C17/'Analysis Summary'!$C$6 -> 0.026086957
B19: Most Common Diseases
B20: Disease | C20: Patient Count | D20: % of Total | E20: Avg. Age of Patients
B21: Hypertension | C21: =COUNTIF('Cleaned Data'!E2:E231,"Hypertension") -> 43 | D21: =C21/'Analysis Summary'!$C$6 -> 0.18695652 | E21: =ROUND(AVERAGEIFS('Cleaned Data'!C2:C231,'Cleaned Data'!E2:E231,B21),1) -> 48.6
B22: Diabetes | C22: =COUNTIF('Cleaned Data'!E2:E231,"Diabetes") -> 30 | D22: =C22/'Analysis Summary'!$C$6 -> 0.13043478 | E22: =ROUND(AVERAGEIFS('Cleaned Data'!C2:C231,'Cleaned Data'!E2:E231,B22),1) -> 46.2
B23: Flu | C23: =COUNTIF('Cleaned Data'!E2:E231,"Flu") -> 22 | D23: =C23/'Analysis Summary'!$C$6 -> 0.095652174 | E23: =ROUND(AVERAGEIFS('Cleaned Data'!C2:C231,'Cleaned Data'!E2:E231,B23),1) -> 49.6
B24: Migraine | C24: =COUNTIF('Cleaned Data'!E2:E231,"Migraine") -> 19 | D24: =C24/'Analysis Summary'!$C$6 -> 0.082608696 | E24: =ROUND(AVERAGEIFS('Cleaned Data'!C2:C231,'Cleaned Data'!E2:E231,B24),1) -> 40.1
B25: Asthma | C25: =COUNTIF('Cleaned Data'!E2:E231,"Asthma") -> 18 | D25: =C25/'Analysis Summary'!$C$6 -> 0.07826087 | E25: =ROUND(AVERAGEIFS('Cleaned Data'!C2:C231,'Cleaned Data'!E2:E231,B25),1) -> 49.9
B26: Anemia | C26: =COUNTIF('Cleaned Data'!E2:E231,"Anemia") -> 16 | D26: =C26/'Analysis Summary'!$C$6 -> 0.069565217 | E26: =ROUND(AVERAGEIFS('Cleaned Data'!C2:C231,'Cleaned Data'!E2:E231,B26),1) -> 44.3
B27: Arthritis | C27: =COUNTIF('Cleaned Data'!E2:E231,"Arthritis") -> 14 | D27: =C27/'Analysis Summary'!$C$6 -> 0.060869565 | E27: =ROUND(AVERAGEIFS('Cleaned Data'!C2:C231,'Cleaned Data'!E2:E231,B27),1) -> 50.4
B28: Bronchitis | C28: =COUNTIF('Cleaned Data'!E2:E231,"Bronchitis") -> 14 | D28: =C28/'Analysis Summary'!$C$6 -> 0.060869565 | E28: =ROUND(AVERAGEIFS('Cleaned Data'!C2:C231,'Cleaned Data'!E2:E231,B28),1) -> 48.6
B29: Obesity | C29: =COUNTIF('Cleaned Data'!E2:E231,"Obesity") -> 12 | D29: =C29/'Analysis Summary'!$C$6 -> 0.052173913 | E29: =ROUND(AVERAGEIFS('Cleaned Data'!C2:C231,'Cleaned Data'!E2:E231,B29),1) -> 35.2
B30: Allergy | C30: =COUNTIF('Cleaned Data'!E2:E231,"Allergy") -> 10 | D30: =C30/'Analysis Summary'!$C$6 -> 0.043478261 | E30: =ROUND(AVERAGEIFS('Cleaned Data'!C2:C231,'Cleaned Data'!E2:E231,B30),1) -> 48.8
B31: Not Specified | C31: =COUNTIF('Cleaned Data'!E2:E231,"Not Specified") -> 9 | D31: =C31/'Analysis Summary'!$C$6 -> 0.039130435 | E31: =ROUND(AVERAGEIFS('Cleaned Data'!C2:C231,'Cleaned Data'!E2:E231,B31),1) -> 47.2
B32: Thyroid Disorder | C32: =COUNTIF('Cleaned Data'!E2:E231,"Thyroid Disorder") -> 8 | D32: =C32/'Analysis Summary'!$C$6 -> 0.034782609 | E32: =ROUND(AVERAGEIFS('Cleaned Data'!C2:C231,'Cleaned Data'!E2:E231,B32),1) -> 54.4
B33: Depression | C33: =COUNTIF('Cleaned Data'!E2:E231,"Depression") -> 7 | D33: =C33/'Analysis Summary'!$C$6 -> 0.030434783 | E33: =ROUND(AVERAGEIFS('Cleaned Data'!C2:C231,'Cleaned Data'!E2:E231,B33),1) -> 39.3
B34: Covid-19 | C34: =COUNTIF('Cleaned Data'!E2:E231,"Covid-19") -> 5 | D34: =C34/'Analysis Summary'!$C$6 -> 0.02173913 | E34: =ROUND(AVERAGEIFS('Cleaned Data'!C2:C231,'Cleaned Data'!E2:E231,B34),1) -> 43.8
B35: Gastritis | C35: =COUNTIF('Cleaned Data'!E2:E231,"Gastritis") -> 3 | D35: =C35/'Analysis Summary'!$C$6 -> 0.013043478 | E35: =ROUND(AVERAGEIFS('Cleaned Data'!C2:C231,'Cleaned Data'!E2:E231,B35),1) -> 27.7
B37: Most Prescribed Medications
B38: Medication | C38: Times Prescribed | D38: Avg. Dosage (mg)
B39: Amlodipine | C39: =COUNTIF('Cleaned Data'!F2:F231,"Amlodipine") -> 42 | D39: =ROUND(AVERAGEIFS('Cleaned Data'!G2:G231,'Cleaned Data'!F2:F231,B39),1) -> 6.9
B40: Metformin | C40: =COUNTIF('Cleaned Data'!F2:F231,"Metformin") -> 30 | D40: =ROUND(AVERAGEIFS('Cleaned Data'!G2:G231,'Cleaned Data'!F2:F231,B40),1) -> 760.5
B41: Sumatriptan | C41: =COUNTIF('Cleaned Data'!F2:F231,"Sumatriptan") -> 21 | D41: =ROUND(AVERAGEIFS('Cleaned Data'!G2:G231,'Cleaned Data'!F2:F231,B41),1) -> 63.7
B42: Paracetamol | C42: =COUNTIF('Cleaned Data'!F2:F231,"Paracetamol") -> 19 | D42: =ROUND(AVERAGEIFS('Cleaned Data'!G2:G231,'Cleaned Data'!F2:F231,B42),1) -> 562.4
B43: Salbutamol | C43: =COUNTIF('Cleaned Data'!F2:F231,"Salbutamol") -> 18 | D43: =ROUND(AVERAGEIFS('Cleaned Data'!G2:G231,'Cleaned Data'!F2:F231,B43),1) -> 153.9
B44: Ibuprofen | C44: =COUNTIF('Cleaned Data'!F2:F231,"Ibuprofen") -> 16 | D44: =ROUND(AVERAGEIFS('Cleaned Data'!G2:G231,'Cleaned Data'!F2:F231,B44),1) -> 331.5
B45: Ferrous Sulfate | C45: =COUNTIF('Cleaned Data'!F2:F231,"Ferrous Sulfate") -> 16 | D45: =ROUND(AVERAGEIFS('Cleaned Data'!G2:G231,'Cleaned Data'!F2:F231,B45),1) -> 253.8
...

Sheet Visualizations
B2: Data Visualizations
B3: Disease distribution, age distribution, gender ratio & medication usage — cleaned dataset
B5: Disease Distribution
B6: Disease | C6: Patient Count | D6: % of Total
B7: Hypertension | C7: =COUNTIF('Cleaned Data'!E2:E231,"Hypertension") -> 43 | D7: =C7/'Analysis Summary'!$C$6 -> 0.18695652
B8: Diabetes | C8: =COUNTIF('Cleaned Data'!E2:E231,"Diabetes") -> 30 | D8: =C8/'Analysis Summary'!$C$6 -> 0.13043478
B9: Flu | C9: =COUNTIF('Cleaned Data'!E2:E231,"Flu") -> 22 | D9: =C9/'Analysis Summary'!$C$6 -> 0.095652174
B10: Migraine | C10: =COUNTIF('Cleaned Data'!E2:E231,"Migraine") -> 19 | D10: =C10/'Analysis Summary'!$C$6 -> 0.082608696
B11: Asthma | C11: =COUNTIF('Cleaned Data'!E2:E231,"Asthma") -> 18 | D11: =C11/'Analysis Summary'!$C$6 -> 0.07826087
B12: Anemia | C12: =COUNTIF('Cleaned Data'!E2:E231,"Anemia") -> 16 | D12: =C12/'Analysis Summary'!$C$6 -> 0.069565217
B13: Arthritis | C13: =COUNTIF('Cleaned Data'!E2:E231,"Arthritis") -> 14 | D13: =C13/'Analysis Summary'!$C$6 -> 0.060869565
B14: Bronchitis | C14: =COUNTIF('Cleaned Data'!E2:E231,"Bronchitis") -> 14 | D14: =C14/'Analysis Summary'!$C$6 -> 0.060869565
B15: Obesity | C15: =COUNTIF('Cleaned Data'!E2:E231,"Obesity") -> 12 | D15: =C15/'Analysis Summary'!$C$6 -> 0.052173913
B16: Allergy | C16: =COUNTIF('Cleaned Data'!E2:E231,"Allergy") -> 10 | D16: =C16/'Analysis Summary'!$C$6 -> 0.043478261
B17: Not Specified | C17: =COUNTIF('Cleaned Data'!E2:E231,"Not Specified") -> 9 | D17: =C17/'Analysis Summary'!$C$6 -> 0.039130435
B18: Thyroid Disorder | C18: =COUNTIF('Cleaned Data'!E2:E231,"Thyroid Disorder") -> 8 | D18: =C18/'Analysis Summary'!$C$6 -> 0.034782609
B19: Depression | C19: =COUNTIF('Cleaned Data'!E2:E231,"Depression") -> 7 | D19: =C19/'Analysis Summary'!$C$6 -> 0.030434783
B20: Covid-19 | C20: =COUNTIF('Cleaned Data'!E2:E231,"Covid-19") -> 5 | D20: =C20/'Analysis Summary'!$C$6 -> 0.02173913
B21: Gastritis | C21: =COUNTIF('Cleaned Data'!E2:E231,"Gastritis") -> 3 | D21: =C21/'Analysis Summary'!$C$6 -> 0.013043478
B24: Age Distribution
B25: Age Range | C25: Patient Count | D25: % of Total
B26: 0-10 | C26: =COUNTIFS('Cleaned Data'!C2:C231,">=0",'Cleaned Data'!C2:C231,"<=10") -> 3 | D26: =C26/'Analysis Summary'!$C$6 -> 0.013043478
B27: 11-20 | C27: =COUNTIFS('Cleaned Data'!C2:C231,">=11",'Cleaned Data'!C2:C231,"<=20") -> 12 | D27: =C27/'Analysis Summary'!$C$6 -> 0.052173913
B28: 21-30 | C28: =COUNTIFS('Cleaned Data'!C2:C231,">=21",'Cleaned Data'!C2:C231,"<=30") -> 28 | D28: =C28/'Analysis Summary'!$C$6 -> 0.12173913
B29: 31-40 | C29: =COUNTIFS('Cleaned Data'!C2:C231,">=31",'Cleaned Data'!C2:C231,"<=40") -> 38 | D29: =C29/'Analysis Summary'!$C$6 -> 0.16521739
B30: 41-50 | C30: =COUNTIFS('Cleaned Data'!C2:C231,">=41",'Cleaned Data'!C2:C231,"<=50") -> 62 | D30: =C30/'Analysis Summary'!$C$6 -> 0.26956522
B31: 51-60 | C31: =COUNTIFS('Cleaned Data'!C2:C231,">=51",'Cleaned Data'!C2:C231,"<=60") -> 41 | D31: =C31/'Analysis Summary'!$C$6 -> 0.17826087
B32: 61-70 | C32: =COUNTIFS('Cleaned Data'!C2:C231,">=61",'Cleaned Data'!C2:C231,"<=70") -> 24 | D32: =C32/'Analysis Summary'!$C$6 -> 0.10434783
B33: 71-80 | C33: =COUNTIFS('Cleaned Data'!C2:C231,">=71",'Cleaned Data'!C2:C231,"<=80") -> 11 | D33: =C33/'Analysis Summary'!$C$6 -> 0.047826087
B34: 81-90 | C34: =COUNTIFS('Cleaned Data'!C2:C231,">=81",'Cleaned Data'!C2:C231,"<=90") -> 10 | D34: =C34/'Analysis Summary'!$C$6 -> 0.043478261
B35: 91-100 | C35: =COUNTIFS('Cleaned Data'!C2:C231,">=91",'Cleaned Data'!C2:C231,"<=100") -> 1 | D35: =C35/'Analysis Summary'!$C$6 -> 0.0043478261
B38: Gender Ratio
B39: Gender | C39: Patient Count | D39: % of Total
B40: Male | C40: =COUNTIF('Cleaned Data'!D2:D231,"Male") -> 114 | D40: =C40/'Analysis Summary'!$C$6 -> 0.49565217
B41: Female | C41: =COUNTIF('Cleaned Data'!D2:D231,"Female") -> 110 | D41: =C41/'Analysis Summary'!$C$6 -> 0.47826087
B42: Unknown | C42: =COUNTIF('Cleaned Data'!D2:D231,"Unknown") -> 6 | D42: =C42/'Analysis Summary'!$C$6 -> 0.026086957
B45: Medication Usage
B46: Medication | C46: Times Prescribed | D46: % of Total
B47: Amlodipine | C47: =COUNTIF('Cleaned Data'!F2:F231,"Amlodipine") -> 42 | D47: =C47/'Analysis Summary'!$C$6 -> 0.1826087
B48: Metformin | C48: =COUNTIF('Cleaned Data'!F2:F231,"Metformin") -> 30 | D48: =C48/'Analysis Summary'!$C$6 -> 0.13043478
...

Sheet Pharmacy Sales Data
A1: Pharmacy Sales Data (Cleaned)
A2: 616 transactions, 2025-09 to 2026-08. Cleaning applied: 15 duplicate transactions removed; 15 missing unit prices imputed using that product's median price, and Revenue recalculated as Quantity × Unit Price.
A4: TransactionID | B4: Sale_Date | C4: Medicine | D4: Brand_Type | E4: Product_Name | F4: Quantity_Sold | G4: Unit_Price | H4: Revenue
A5: TXN00032 | B5: 45929 | C5: Amlodipine | D5: Generic | E5: Amlodipine (Generic) | F5: 2 | G5: 15 | H5: 30
A6: TXN00484 | B6: 46202 | C6: Metformin | D6: Generic | E6: Metformin (Generic) | F6: 6 | G6: 21.56 | H6: 129.36
A7: TXN00077 | B7: 45945 | C7: Favipiravir | D7: Branded | E7: Viroguard | F7: 1 | G7: 223.09 | H7: 223.09
A8: TXN00329 | B8: 46115 | C8: Sumatriptan | D8: Branded | E8: Migranil | F8: 2 | G8: 231.47 | H8: 462.94
A9: TXN00255 | B9: 46075 | C9: Paracetamol | D9: Generic | E9: Paracetamol (Generic) | F9: 3 | G9: 9.97 | H9: 29.91
A10: TXN00052 | B10: 45961 | C10: Salbutamol | D10: Generic | E10: Salbutamol (Generic) | F10: 2 | G10: 58.33 | H10: 116.66
A11: TXN00241 | B11: 46070 | C11: Amlodipine | D11: Generic | E11: Amlodipine (Generic) | F11: 2 | G11: 15.96 | H11: 31.92
A12: TXN00214 | B12: 46038 | C12: Ibuprofen | D12: Generic | E12: Ibuprofen (Generic) | F12: 2 | G12: 18.26 | H12: 36.52
A13: TXN00308 | B13: 46093 | C13: Metformin | D13: Branded | E13: Glucofit | F13: 5 | G13: 46.35 | H13: 231.75
A14: TXN00335 | B14: 46131 | C14: Metformin | D14: Generic | E14: Metformin (Generic) | F14: 3 | G14: 19.08 | H14: 57.24
A15: TXN00196 | B15: 46038 | C15: Salbutamol | D15: Generic | E15: Salbutamol (Generic) | F15: 2 | G15: 57.85 | H15: 115.7
A16: TXN00467 | B16: 46188 | C16: Metformin | D16: Generic | E16: Metformin (Generic) | F16: 1 | G16: 18.88 | H16: 18.88
... A620: TXN00185 | B620: 46026 | C620: Orlistat | D620: Branded | E620: Slimolate | F620: 3 | G620: 365.86 | H620: 1097.58

Sheet Pharmacy Sales Analysis
B2: Pharmacy Sales Analysis
B3: Top-selling medicines, monthly growth, and branded vs. generic performance
B5: Top-Selling Medicines
B6: Medicine | C6: Units Sold | D6: Total Revenue | E6: % of Total Revenue
B7: Sumatriptan | C7: =SUMIF('Pharmacy Sales Data'!$C$5:$C$620,B7,'Pharmacy Sales Data'!$F$5:$F$620) -> 149 | D7: =SUMIF('Pharmacy Sales Data'!$C$5:$C$620,B7,'Pharmacy Sales Data'!$H$5:$H$620) -> 22266.14 | E7: =D7/$D$22 -> 0.18888326
B8: Orlistat | C8: =SUMIF('Pharmacy Sales Data'!$C$5:$C$620,B8,'Pharmacy Sales Data'!$F$5:$F$620) -> 95 | D8: =SUMIF('Pharmacy Sales Data'!$C$5:$C$620,B8,'Pharmacy Sales Data'!$H$5:$H$620) -> 20085.71 | E8: =D8/$D$22 -> 0.17038671
B9: Salbutamol | C9: =SUMIF('Pharmacy Sales Data'!$C$5:$C$620,B9,'Pharmacy Sales Data'!$F$5:$F$620) -> 195 | D9: =SUMIF('Pharmacy Sales Data'!$C$5:$C$620,B9,'Pharmacy Sales Data'!$H$5:$H$620) -> 15120.41 | E9: =D9/$D$22 -> 0.12826616
B10: Azithromycin | C10: =SUMIF('Pharmacy Sales Data'!$C$5:$C$620,B10,'Pharmacy Sales Data'!$F$5:$F$620) -> 124 | D10: =SUMIF('Pharmacy Sales Data'!$C$5:$C$620,B10,'Pharmacy Sales Data'!$H$5:$H$620) -> 9182.09 | E10: =D10/$D$22 -> 0.077891501
B11: Amlodipine | C11: =SUMIF('Pharmacy Sales Data'!$C$5:$C$620,B11,'Pharmacy Sales Data'!$F$5:$F$620) -> 372 | D11: =SUMIF('Pharmacy Sales Data'!$C$5:$C$620,B11,'Pharmacy Sales Data'!$H$5:$H$620) -> 8832.63 | E11: =D11/$D$22 -> 0.074927038
B12: Metformin | C12: =SUMIF('Pharmacy Sales Data'!$C$5:$C$620,B12,'Pharmacy Sales Data'!$F$5:$F$620) -> 290 | D12: =SUMIF('Pharmacy Sales Data'!$C$5:$C$620,B12,'Pharmacy Sales Data'!$H$5:$H$620) -> 8424.16 | E12: =D12/$D$22 -> 0.071461994
B13: Sertraline | C13: =SUMIF('Pharmacy Sales Data'!$C$5:$C$620,B13,'Pharmacy Sales Data'!$F$5:$F$620) -> 80 | D13: =SUMIF('Pharmacy Sales Data'!$C$5:$C$620,B13,'Pharmacy Sales Data'!$H$5:$H$620) -> 8102.92 | E13: =D13/$D$22 -> 0.068736921
B14: Favipiravir | C14: =SUMIF('Pharmacy Sales Data'!$C$5:$C$620,B14,'Pharmacy Sales Data'!$F$5:$F$620) -> 43 | D14: =SUMIF('Pharmacy Sales Data'!$C$5:$C$620,B14,'Pharmacy Sales Data'!$H$5:$H$620) -> 6788.02 | E14: =D14/$D$22 -> 0.057582649
B15: Ferrous Sulfate | C15: =SUMIF('Pharmacy Sales Data'!$C$5:$C$620,B15,'Pharmacy Sales Data'!$F$5:$F$620) -> 121 | D15: =SUMIF('Pharmacy Sales Data'!$C$5:$C$620,B15,'Pharmacy Sales Data'!$H$5:$H$620) -> 4834.08 | E15: =D15/$D$22 -> 0.041007412
B16: Ibuprofen | C16: =SUMIF('Pharmacy Sales Data'!$C$5:$C$620,B16,'Pharmacy Sales Data'!$F$5:$F$620) -> 140 | D16: =SUMIF('Pharmacy Sales Data'!$C$5:$C$620,B16,'Pharmacy Sales Data'!$H$5:$H$620) -> 4332.04 | E16: =D16/$D$22 -> 0.036748616
B17: Paracetamol | C17: =SUMIF('Pharmacy Sales Data'!$C$5:$C$620,B17,'Pharmacy Sales Data'!$F$5:$F$620) -> 253 | D17: =SUMIF('Pharmacy Sales Data'!$C$5:$C$620,B17,'Pharmacy Sales Data'!$H$5:$H$620) -> 3934.25 | E17: =D17/$D$22 -> 0.03337417
B18: Omeprazole | C18: =SUMIF('Pharmacy Sales Data'!$C$5:$C$620,B18,'Pharmacy Sales Data'!$F$5:$F$620) -> 71 | D18: =SUMIF('Pharmacy Sales Data'!$C$5:$C$620,B18,'Pharmacy Sales Data'!$H$5:$H$620) -> 3059.99 | E18: =D18/$D$22 -> 0.025957839
... B20: Levothyroxine | C20: =SUMIF('Pharmacy Sales Data'!$C$5:$C$620,B20,'Pharmacy Sales Data'!$F$5:$F$620) -> 32 | D20: =SUMIF('Pharmacy Sales Data'!$C$5:$C$620,B20,'Pharmacy Sales Data'!$H$5:$H$620) -> 1210.71 | E20: =D20/$D$22 -> 0.010270431
B22: Total | D22: =SUM(D7:D20) -> 117883.08
B24: Monthly Sales Trend
B25: Month | C25: Revenue | D25: Units Sold | E25: Growth % (vs. prior month)
B26: Sep-2025 | C26: =SUMIFS('Pharmacy Sales Data'!$H$5:$H$620,'Pharmacy Sales Data'!$B$5:$B$620,">="&DATE(2025,9,1),'Pharmacy Sales Data'!$B$5:$B$620,"<="&DATE(2025,9,30)) -> 6151.24 | D26: =SUMIFS('Pharmacy Sales Data'!$F$5:$F$620,'Pharmacy Sales Data'!$B$5:$B$620,">="&DATE(2025,9,1),'Pharmacy Sales Data'!$B$5:$B$620,"<="&DATE(2025,9,30)) -> 114 | E26: —
B27: Oct-2025 | C27: =SUMIFS('Pharmacy Sales Data'!$H$5:$H$620,'Pharmacy Sales Data'!$B$5:$B$620,">="&DATE(2025,10,1),'Pharmacy Sales Data'!$B$5:$B$620,"<="&DATE(2025,10,31)) -> 5640.03 | D27: =SUMIFS('Pharmacy Sales Data'!$F$5:$F$620,'Pharmacy Sales Data'!$B$5:$B$620,">="&DATE(2025,10,1),'Pharmacy Sales Data'!$B$5:$B$620,"<="&DATE(2025,10,31)) -> 135 | E27: =(C27-C26)/C26 -> -0.083106821
B28: Nov-2025 | C28: =SUMIFS('Pharmacy Sales Data'!$H$5:$H$620,'Pharmacy Sales Data'!$B$5:$B$620,">="&DATE(2025,11,1),'Pharmacy Sales Data'!$B$5:$B$620,"<="&DATE(2025,11,30)) -> 10409.97 | D28: =SUMIFS('Pharmacy Sales Data'!$F$5:$F$620,'Pharmacy Sales Data'!$B$5:$B$620,">="&DATE(2025,11,1),'Pharmacy Sales Data'!$B$5:$B$620,"<="&DATE(2025,11,30)) -> 152 | E28: =(C28-C27)/C27 -> 0.84572954
B29: Dec-2025 | C29: =SUMIFS('Pharmacy Sales Data'!$H$5:$H$620,'Pharmacy Sales Data'!$B$5:$B$620,">="&DATE(2025,12,1),'Pharmacy Sales Data'!$B$5:$B$620,"<="&DATE(2025,12,31)) -> 6230.9 | D29: =SUMIFS('Pharmacy Sales Data'!$F$5:$F$620,'Pharmacy Sales Data'!$B$5:$B$620,">="&DATE(2025,12,1),'Pharmacy Sales Data'!$B$5:$B$620,"<="&DATE(2025,12,31)) -> 141 | E29: =(C29-C28)/C28 -> -0.4014488
B30: Jan-2026 | C30: =SUMIFS('Pharmacy Sales Data'!$H$5:$H$620,'Pharmacy Sales Data'!$B$5:$B$620,">="&DATE(2026,1,1),'Pharmacy Sales Data'!$B$5:$B$620,"<="&DATE(2026,1,31)) -> 8785.45 | D30: =SUMIFS('Pharmacy Sales Data'!$F$5:$F$620,'Pharmacy Sales Data'!$B$5:$B$620,">="&DATE(2026,1,1),'Pharmacy Sales Data'!$B$5:$B$620,"<="&DATE(2026,1,31)) -> 146 | E30: =(C30-C29)/C29 -> 0.4099809
B31: Feb-2026 | C31: =SUMIFS('Pharmacy Sales Data'!$H$5:$H$620,'Pharmacy Sales Data'!$B$5:$B$620,">="&DATE(2026,2,1),'Pharmacy Sales Data'!$B$5:$B$620,"<="&DATE(2026,2,28)) -> 9982.32 | D31: =SUMIFS('Pharmacy Sales Data'!$F$5:$F$620,'Pharmacy Sales Data'!$B$5:$B$620,">="&DATE(2026,2,1),'Pharmacy Sales Data'!$B$5:$B$620,"<="&DATE(2026,2,28)) -> 141 | E31: =(C31-C30)/C30 -> 0.1362332
B32: Mar-2026 | C32: =SUMIFS('Pharmacy Sales Data'!$H$5:$H$620,'Pharmacy Sales Data'!$B$5:$B$620,">="&DATE(2026,3,1),'Pharmacy Sales Data'!$B$5:$B$620,"<="&DATE(2026,3,31)) -> 12241.83 | D32: =SUMIFS('Pharmacy Sales Data'!$F$5:$F$620,'Pharmacy Sales Data'!$B$5:$B$620,">="&DATE(2026,3,1),'Pharmacy Sales Data'!$B$5:$B$620,"<="&DATE(2026,3,31)) -> 174 | E32: =(C32-C31)/C31 -> 0.22635119
B33: Apr-2026 | C33: =SUMIFS('Pharmacy Sales Data'!$H$5:$H$620,'Pharmacy Sales Data'!$B$5:$B$620,">="&DATE(2026,4,1),'Pharmacy Sales Data'!$B$5:$B$620,"<="&DATE(2026,4,30)) -> 10492.72 | D33: =SUMIFS('Pharmacy Sales Data'!$F$5:$F$620,'Pharmacy Sales Data'!$B$5:$B$620,">="&DATE(2026,4,1),'Pharmacy Sales Data'!$B$5:$B$620,"<="&DATE(2026,4,30)) -> 213 | E33: =(C33-C32)/C32 -> -0.14287978
B34: May-2026 | C34: =SUMIFS('Pharmacy Sales Data'!$H$5:$H$620,'Pharmacy Sales Data'!$B$5:$B$620,">="&DATE(2026,5,1),'Pharmacy Sales Data'!$B$5:$B$620,"<="&DATE(2026,5,31)) -> 12543.01 | D34: =SUMIFS('Pharmacy Sales Data'!$F$5:$F$620,'Pharmacy Sales Data'!$B$5:$B$620,">="&DATE(2026,5,1),'Pharmacy Sales Data'!$B$5:$B$620,"<="&DATE(2026,5,31)) -> 229 | E34: =(C34-C33)/C33 -> 0.19540119
B35: Jun-2026 | C35: =SUMIFS('Pharmacy Sales Data'!$H$5:$H$620,'Pharmacy Sales Data'!$B$5:$B$620,">="&DATE(2026,6,1),'Pharmacy Sales Data'!$B$5:$B$620,"<="&DATE(2026,6,30)) -> 11142.52 | D35: =SUMIFS('Pharmacy Sales Data'!$F$5:$F$620,'Pharmacy Sales Data'!$B$5:$B$620,">="&DATE(2026,6,1),'Pharmacy Sales Data'!$B$5:$B$620,"<="&DATE(2026,6,30)) -> 216 | E35: =(C35-C34)/C34 -> -0.11165502
B36: Jul-2026 | C36: =SUMIFS('Pharmacy Sales Data'!$H$5:$H$620,'Pharmacy Sales Data'!$B$5:$B$620,">="&DATE(2026,7,1),'Pharmacy Sales Data'!$B$5:$B$620,"<="&DATE(2026,7,31)) -> 14877.2 | D36: =SUMIFS('Pharmacy Sales Data'!$F$5:$F$620,'Pharmacy Sales Data'!$B$5:$B$620,">="&DATE(2026,7,1),'Pharmacy Sales Data'!$B$5:$B$620,"<="&DATE(2026,7,31)) -> 231 | E36: =(C36-C35)/C35 -> 0.33517373
B37: Aug-2026 | C37: =SUMIFS('Pharmacy Sales Data'!$H$5:$H$620,'Pharmacy Sales Data'!$B$5:$B$620,">="&DATE(2026,8,1),'Pharmacy Sales Data'!$B$5:$B$620,"<="&DATE(2026,8,31)) -> 9385.89 | D37: =SUMIFS('Pharmacy Sales Data'!$F$5:$F$620,'Pharmacy Sales Data'!$B$5:$B$620,">="&DATE(2026,8,1),'Pharmacy Sales Data'!$B$5:$B$620,"<="&DATE(2026,8,31)) -> 182 | E37: =(C37-C36)/C36 -> -0.36910911
B39: Branded vs. Generic Comparison
B40: Type | C40: Units Sold | D40: Total Revenue | E40: % of Total Revenue | F40: Avg. Unit Price
B41: Branded | C41: =SUMIF('Pharmacy Sales Data'!$D$5:$D$620,B41,'Pharmacy Sales Data'!$F$5:$F$620) -> 800 | D41: =SUMIF('Pharmacy Sales Data'!$D$5:$D$620,B41,'Pharmacy Sales Data'!$H$5:$H$620) -> 68008.99 | E41: =D41/$D$22 -> 0.57691901 | F41: =AVERAGEIF('Pharmacy Sales Data'!$D$5:$D$620,B41,'Pharmacy Sales Data'!$G$5:$G$620) -> 88.43807
B42: Generic | C42: =SUMIF('Pharmacy Sales Data'!$D$5:$D$620,B42,'Pharmacy Sales Data'!$F$5:$F$620) -> 1274 | D42: =SUMIF('Pharmacy Sales Data'!$D$5:$D$620,B42,'Pharmacy Sales Data'!$H$5:$H$620) -> 49874.09 | E42: =D42/$D$22 -> 0.42308099 | F42: =AVERAGEIF('Pharmacy Sales Data'!$D$5:$D$620,B42,'Pharmacy Sales Data'!$G$5:$G$620) -> 39.124742

Sheet ADR Patient Data
A1: ADR Patient Data (Synthetic)
A2: 520 simulated patients, one medication course each, with an optional observed symptom and its onset date relative to the medication start date. Generated for this exercise to demonstrate adverse-drug-reaction signal detection — not real patient data.
A4: PatientID | B4: Medication | C4: Medication_Start_Date | D4: Symptom | E4: Symptom_Onset_Date | F4: Days_to_Onset | G4: Severity
A5: AD0001 | B5: Levothyroxine | C5: 45916 | D5: None
A6: AD0002 | B6: Salbutamol | C6: 45855 | D6: None
A7: AD0003 | B7: Metformin | C7: 45957 | D7: None
A8: AD0004 | B8: Orlistat | C8: 45901 | D8: Diarrhea | E8: 45909 | F8: 8 | G8: Severe
A9: AD0005 | B9: Paracetamol | C9: 45853 | D9: None
A10: AD0006 | B10: Favipiravir | C10: 46055 | D10: Nausea | E10: 46061 | F10: 6 | G10: Mild
A11: AD0007 | B11: Ibuprofen | C11: 46138 | D11: None
A12: AD0008 | B12: Salbutamol | C12: 45731 | D12: Palpitations | E12: 45734 | F12: 3 | G12: Mild
A13: AD0009 | B13: Levothyroxine | C13: 45875 | D13: None
A14: AD0010 | B14: Favipiravir | C14: 45747 | D14: Nausea | E14: 45751 | F14: 4 | G14: Severe
A15: AD0011 | B15: Levothyroxine | C15: 45767 | D15: None
A16: AD0012 | B16: Cetirizine | C16: 45782 | D16: None
A17: AD0013 | B17: Orlistat | C17: 45715 | D17: None
A18: AD0014 | B18: Levothyroxine | C18: 46071 | D18: None
A19: AD0015 | B19: Sertraline | C19: 45911 | D19: Insomnia | E19: 45918 | F19: 7 | G19: Severe
A20: AD0016 | B20: Amlodipine | C20: 45711 | D20: None
A21: AD0017 | B21: Amlodipine | C21: 46024 | D21: None
A22: AD0018 | B22: Ferrous Sulfate | C22: 45778 | D22: Nausea | E22: 45781 | F22: 3 | G22: Mild
A23: AD0019 | B23: Azithromycin | C23: 45755 | D23: Diarrhea | E23: 45767 | F23: 12 | G23: Severe
A24: AD0020 | B24: Levothyroxine | C24: 46083 | D24: None
A25: AD0021 | B25: Amlodipine | C25: 46150 | D25: Vomiting | E25: 46154 | F25: 4 | G25: Moderate
A26: AD0022 | B26: Salbutamol | C26: 45748 | D26: None
A27: AD0023 | B27: Azithromycin | C27: 45774 | D27: None
A28: AD0024 | B28: Azithromycin | C28: 45763 | D28: None
A29: AD0025 | B29: Paracetamol | C29: 45903 | D29: None
A30: AD0026 | B30: Levothyroxine | C30: 45746 | D30: None
A31: AD0027 | B31: Paracetamol | C31: 45683 | D31: Swelling | E31: 45748 | F31: 65 | G31: Moderate
A32: AD0028 | B32: Sertraline | C32: 46085 | D32: None
A33: AD0029 | B33: Ibuprofen | C33: 45763 | D33: None
A34: AD0030 | B34: Ferrous Sulfate | C34: 45960 | D34: None
A35: AD0031 | B35: Ibuprofen | C35: 46122 | D35: None
A36: AD0032 | B36: Amlodipine | C36: 46156 | D36: Swelling | E36: 46157 | F36: 1 | G36: Mild
A37: AD0033 | B37: Cetirizine | C37: 45769 | D37: None
A38: AD0034 | B38: Cetirizine | C38: 45743 | D38: None
A39: AD0035 | B39: Paracetamol | C39: 45769 | D39: None
A40: AD0036 | B40: Ferrous Sulfate | C40: 45948 | D40: None
A41: AD0037 | B41: Azithromycin | C41: 46069 | D41: Diarrhea | E41: 46102 | F41: 33 | G41: Mild
...

Sheet ADR Signal Analysis
B2: Adverse Drug Reaction (ADR) Signal Analysis
B3: High-risk medicines, drug–symptom correlation, and onset timelines (synthetic data)
B5: ⚠ Educational exercise on fully synthetic data. This sheet demonstrates a simplified Proportional Reporting Ratio (PRR) — the same style of disproportionality method used in real pharmacovigilance systems (e.g. WHO VigiBase, FDA FAERS). PRR ≥ 2 with ≥ 3 cases is a common screening threshold, but it flags a statistical association for further review — it is NOT proof of causation. Real ADR assessment needs clinical judgement and validated tools (e.g. the Naranjo scale, WHO-UMC causality categories). Do not use this workbook for real clinical or regulatory decisions.
B7: High-Risk Medicines (Overall ADR Rate)
B8: Medication | C8: Prescribed (n) | D8: With Symptom (n) | E8: ADR Rate %
B9: Orlistat | C9: =COUNTIF('ADR Patient Data'!$B$5:$B$524,B9) -> 41 | D9: =COUNTIFS('ADR Patient Data'!$B$5:$B$524,B9,'ADR Patient Data'!$D$5:$D$524,"<>None") -> 20 | E9: =D9/C9 -> 0.48780488
B10: Metformin | C10: =COUNTIF('ADR Patient Data'!$B$5:$B$524,B10) -> 34 | D10: =COUNTIFS('ADR Patient Data'!$B$5:$B$524,B10,'ADR Patient Data'!$D$5:$D$524,"<>None") -> 12 | E10: =D10/C10 -> 0.35294118
B11: Ferrous Sulfate | C11: =COUNTIF('ADR Patient Data'!$B$5:$B$524,B11) -> 45 | D11: =COUNTIFS('ADR Patient Data'!$B$5:$B$524,B11,'ADR Patient Data'!$D$5:$D$524,"<>None") -> 15 | E11: =D11/C11 -> 0.33333333
B12: Amlodipine | C12: =COUNTIF('ADR Patient Data'!$B$5:$B$524,B12) -> 45 | D12: =COUNTIFS('ADR Patient Data'!$B$5:$B$524,B12,'ADR Patient Data'!$D$5:$D$524,"<>None") -> 14 | E12: =D12/C12 -> 0.31111111
B13: Sertraline | C13: =COUNTIF('ADR Patient Data'!$B$5:$B$524,B13) -> 27 | D13: =COUNTIFS('ADR Patient Data'!$B$5:$B$524,B13,'ADR Patient Data'!$D$5:$D$524,"<>None") -> 8 | E13: =D13/C13 -> 0.2962963
B14: Salbutamol | C14: =COUNTIF('ADR Patient Data'!$B$5:$B$524,B14) -> 29 | D14: =COUNTIFS('ADR Patient Data'!$B$5:$B$524,B14,'ADR Patient Data'!$D$5:$D$524,"<>None") -> 7 | E14: =D14/C14 -> 0.24137931
B15: Omeprazole | C15: =COUNTIF('ADR Patient Data'!$B$5:$B$524,B15) -> 34 | D15: =COUNTIFS('ADR Patient Data'!$B$5:$B$524,B15,'ADR Patient Data'!$D$5:$D$524,"<>None") -> 8 | E15: =D15/C15 -> 0.23529412
B16: Ibuprofen | C16: =COUNTIF('ADR Patient Data'!$B$5:$B$524,B16) -> 35 | D16: =COUNTIFS('ADR Patient Data'!$B$5:$B$524,B16,'ADR Patient Data'!$D$5:$D$524,"<>None") -> 7 | E16: =D16/C16 -> 0.2
B17: Azithromycin | C17: =COUNTIF('ADR Patient Data'!$B$5:$B$524,B17) -> 37 | D17: =COUNTIFS('ADR Patient Data'!$B$5:$B$524,B17,'ADR Patient Data'!$D$5:$D$524,"<>None") -> 7 | E17: =D17/C17 -> 0.18918919
B18: Cetirizine | C18: =COUNTIF('ADR Patient Data'!$B$5:$B$524,B18) -> 40 | D18: =COUNTIFS('ADR Patient Data'!$B$5:$B$524,B18,'ADR Patient Data'!$D$5:$D$524,"<>None") -> 7 | E18: =D18/C18 -> 0.175
B19: Favipiravir | C19: =COUNTIF('ADR Patient Data'!$B$5:$B$524,B19) -> 42 | D19: =COUNTIFS('ADR Patient Data'!$B$5:$B$524,B19,'ADR Patient Data'!$D$5:$D$524,"<>None") -> 7 | E19: =D19/C19 -> 0.16666667
B20: Sumatriptan | C20: =COUNTIF('ADR Patient Data'!$B$5:$B$524,B20) -> 38 | D20: =COUNTIFS('ADR Patient Data'!$B$5:$B$524,B20,'ADR Patient Data'!$D$5:$D$524,"<>None") -> 4 | E20: =D20/C20 -> 0.10526316
... B22: Levothyroxine | C22: =COUNTIF('ADR Patient Data'!$B$5:$B$524,B22) -> 33 | D22: =COUNTIFS('ADR Patient Data'!$B$5:$B$524,B22,'ADR Patient Data'!$D$5:$D$524,"<>None") -> 2 | E22: =D22/C22 -> 0.060606061
B25: Drug–Symptom Signal Detection (Simplified PRR)
B26: Medication | C26: Symptom | D26: Cases | E26: Patients on Drug | F26: Rate on Drug % | G26: Background Rate % | H26: PRR | I26: Signal Flag
B27: Ferrous Sulfate | C27: Constipation | D27: =COUNTIFS('ADR Patient Data'!$B$5:$B$524,B27,'ADR Patient Data'!$D$5:$D$524,C27) -> 5 | E27: =COUNTIF('ADR Patient Data'!$B$5:$B$524,B27) -> 45 | F27: =D27/E27 -> 0.11111111 | G27: =(COUNTIF('ADR Patient Data'!$D$5:$D$524,C27)-D27)/(520-E27) -> 0 | H27: =IF(G27=0,"—",ROUND(F27/G27,2)) -> — | I27: =IF(G27=0,"Possible Signal *",IF(AND(D27>=3,F27/G27>=2),"Possible Signal","Inconclusive")) -> Possible Signal * | J27: =B27&" – "&C27 -> Ferrous Sulfate – Constipation
B28: Salbutamol | C28: Tremor | D28: =COUNTIFS('ADR Patient Data'!$B$5:$B$524,B28,'ADR Patient Data'!$D$5:$D$524,C28) -> 4 | E28: =COUNTIF('ADR Patient Data'!$B$5:$B$524,B28) -> 29 | F28: =D28/E28 -> 0.13793103 | G28: =(COUNTIF('ADR Patient Data'!$D$5:$D$524,C28)-D28)/(520-E28) -> 0 | H28: =IF(G28=0,"—",ROUND(F28/G28,2)) -> — | I28: =IF(G28=0,"Possible Signal *",IF(AND(D28>=3,F28/G28>=2),"Possible Signal","Inconclusive")) -> Possible Signal * | J28: =B28&" – "&C28 -> Salbutamol – Tremor
B29: Orlistat | C29: Vomiting | D29: =COUNTIFS('ADR Patient Data'!$B$5:$B$524,B29,'ADR Patient Data'!$D$5:$D$524,C29) -> 5 | E29: =COUNTIF('ADR Patient Data'!$B$5:$B$524,B29) -> 41 | F29: =D29/E29 -> 0.12195122 | G29: =(COUNTIF('ADR Patient Data'!$D$5:$D$524,C29)-D29)/(520-E29) -> 0.0020876827 | H29: =IF(G29=0,"—",ROUND(F29/G29,2)) -> 58.41 | I29: =IF(G29=0,"Possible Signal *",IF(AND(D29>=3,F29/G29>=2),"Possible Signal","Inconclusive")) -> Possible Signal | J29: =B29&" – "&C29 -> Orlistat – Vomiting
B30: Omeprazole | C30: Headache | D30: =COUNTIFS('ADR Patient Data'!$B$5:$B$524,B30,'ADR Patient Data'!$D$5:$D$524,C30) -> 4 | E30: =COUNTIF('ADR Patient Data'!$B$5:$B$524,B30) -> 34 | F30: =D30/E30 -> 0.11764706 | G30: =(COUNTIF('ADR Patient Data'!$D$5:$D$524,C30)-D30)/(520-E30) -> 0.0041152263 | H30: =IF(G30=0,"—",ROUND(F30/G30,2)) -> 28.59 | I30: =IF(G30=0,"Possible Signal *",IF(AND(D30>=3,F30/G30>=2),"Possible Signal","Inconclusive")) -> Possible Signal | J30: =B30&" – "&C30 -> Omeprazole – Headache
B31: Sertraline | C31: Dry Mouth | D31: =COUNTIFS('ADR Patient Data'!$B$5:$B$524,B31,'ADR Patient Data'!$D$5:$D$524,C31) -> 4 | E31: =COUNTIF('ADR Patient Data'!$B$5:$B$524,B31) -> 27 | F31: =D31/E31 -> 0.14814815 | G31: =(COUNTIF('ADR Patient Data'!$D$5:$D$524,C31)-D31)/(520-E31) -> 0.0060851927 | H31: =IF(G31=0,"—",ROUND(F31/G31,2)) -> 24.35 | I31: =IF(G31=0,"Possible Signal *",IF(AND(D31>=3,F31/G31>=2),"Possible Signal","Inconclusive")) -> Possible Signal | J31: =B31&" – "&C31 -> Sertraline – Dry Mouth
B32: Cetirizine | C32: Drowsiness | D32: =COUNTIFS('ADR Patient Data'!$B$5:$B$524,B32,'ADR Patient Data'!$D$5:$D$524,C32) -> 3 | E32: =COUNTIF('ADR Patient Data'!$B$5:$B$524,B32) -> 40 | F32: =D32/E32 -> 0.075 | G32: =(COUNTIF('ADR Patient Data'!$D$5:$D$524,C32)-D32)/(520-E32) -> 0.0041666667 | H32: =IF(G32=0,"—",ROUND(F32/G32,2)) -> 18 | I32: =IF(G32=0,"Possible Signal *",IF(AND(D32>=3,F32/G32>=2),"Possible Signal","Inconclusive")) -> Possible Signal | J32: =B32&" – "&C32 -> Cetirizine – Drowsiness
B33: Amlodipine | C33: Swelling | D33: =COUNTIFS('ADR Patient Data'!$B$5:$B$524,B33,'ADR Patient Data'!$D$5:$D$524,C33) -> 5 | E33: =COUNTIF('ADR Patient Data'!$B$5:$B$524,B33) -> 45 | F33: =D33/E33 -> 0.11111111 | G33: =(COUNTIF('ADR Patient Data'!$D$5:$D$524,C33)-D33)/(520-E33) -> 0.0063157895 | H33: =IF(G33=0,"—",ROUND(F33/G33,2)) -> 17.59 | I33: =IF(G33=0,"Possible Signal *",IF(AND(D33>=3,F33/G33>=2),"Possible Signal","Inconclusive")) -> Possible Signal | J33: =B33&" – "&C33 -> Amlodipine – Swelling
B34: Orlistat | C34: Fatigue | D34: =COUNTIFS('ADR Patient Data'!$B$5:$B$524,B34,'ADR Patient Data'!$D$5:$D$524,C34) -> 3 | E34: =COUNTIF('ADR Patient Data'!$B$5:$B$524,B34) -> 41 | F34: =D34/E34 -> 0.073170732 | G34: =(COUNTIF('ADR Patient Data'!$D$5:$D$524,C34)-D34)/(520-E34) -> 0.0041753653 | H34: =IF(G34=0,"—",ROUND(F34/G34,2)) -> 17.52 | I34: =IF(G34=0,"Possible Signal *",IF(AND(D34>=3,F34/G34>=2),"Possible Signal","Inconclusive")) -> Possible Signal | J34: =B34&" – "&C34 -> Orlistat – Fatigue
B35: Orlistat | C35: Diarrhea | D35: =COUNTIFS('ADR Patient Data'!$B$5:$B$524,B35,'ADR Patient Data'!$D$5:$D$524,C35) -> 9 | E35: =COUNTIF('ADR Patient Data'!$B$5:$B$524,B35) -> 41 | F35: =D35/E35 -> 0.2195122 | G35: =(COUNTIF('ADR Patient Data'!$D$5:$D$524,C35)-D35)/(520-E35) -> 0.022964509 | H35: =IF(G35=0,"—",ROUND(F35/G35,2)) -> 9.56 | I35: =IF(G35=0,"Possible Signal *",IF(AND(D35>=3,F35/G35>=2),"Possible Signal","Inconclusive")) -> Possible Signal | J35: =B35&" – "&C35 -> Orlistat – Diarrhea
B36: Amlodipine | C36: Dizziness | D36: =COUNTIFS('ADR Patient Data'!$B$5:$B$524,B36,'ADR Patient Data'!$D$5:$D$524,C36) -> 6 | E36: =COUNTIF('ADR Patient Data'!$B$5:$B$524,B36) -> 45 | F36: =D36/E36 -> 0.13333333 | G36: =(COUNTIF('ADR Patient Data'!$D$5:$D$524,C36)-D36)/(520-E36) -> 0.014736842 | H36: =IF(G36=0,"—",ROUND(F36/G36,2)) -> 9.05 | I36: =IF(G36=0,"Possible Signal *",IF(AND(D36>=3,F36/G36>=2),"Possible Signal","Inconclusive")) -> Possible Signal | J36: =B36&" – "&C36 -> Amlodipine – Dizziness
B37: Ferrous Sulfate | C37: Nausea | D37: =COUNTIFS('ADR Patient Data'!$B$5:$B$524,B37,'ADR Patient Data'!$D$5:$D$524,C37) -> 9 | E37: =COUNTIF('ADR Patient Data'!$B$5:$B$524,B37) -> 45 | F37: =D37/E37 -> 0.2 | G37: =(COUNTIF('ADR Patient Data'!$D$5:$D$524,C37)-D37)/(520-E37) -> 0.037894737 | H37: =IF(G37=0,"—",ROUND(F37/G37,2)) -> 5.28 | I37: =IF(G37=0,"Possible Signal *",IF(AND(D37>=3,F37/G37>=2),"Possible Signal","Inconclusive")) -> Possible Signal | J37: =B37&" – "&C37 -> Ferrous Sulfate – Nausea
B38: Metformin | C38: Diarrhea | D38: =COUNTIFS('ADR Patient Data'!$B$5:$B$524,B38,'ADR Patient Data'!$D$5:$D$524,C38) -> 5 | E38: =COUNTIF('ADR Patient Data'!$B$5:$B$524,B38) -> 34 | F38: =D38/E38 -> 0.14705882 | G38: =(COUNTIF('ADR Patient Data'!$D$5:$D$524,C38)-D38)/(520-E38) -> 0.030864198 | H38: =IF(G38=0,"—",ROUND(F38/G38,2)) -> 4.76 | I38: =IF(G38=0,"Possible Signal *",IF(AND(D38>=3,F38/G38>=2),"Possible Signal","Inconclusive")) -> Possible Signal | J38: =B38&" – "&C38 -> Metformin – Diarrhea
... B43: Favipiravir | C43: Nausea | D43: =COUNTIFS('ADR Patient Data'!$B$5:$B$524,B43,'ADR Patient Data'!$D$5:$D$524,C43) -> 3 | E43: =COUNTIF('ADR Patient Data'!$B$5:$B$524,B43) -> 42 | F43: =D43/E43 -> 0.071428571 | G43: =(COUNTIF('ADR Patient Data'!$D$5:$D$524,C43)-D43)/(520-E43) -> 0.050209205 | H43: =IF(G43=0,"—",ROUND(F43/G43,2)) -> 1.42 | I43: =IF(G43=0,"Possible Signal *",IF(AND(D43>=3,F43/G43>=2),"Possible Signal","Inconclusive")) -> Inconclusive | J43: =B43&" – "&C43 -> Favipiravir – Nausea
B44: * “drug-exclusive” — this symptom was not observed on any other medication in the dataset, so a background rate could not be computed.
B46: Onset Timeline for Flagged Signals
B47: Medication | C47: Symptom | D47: Cases | E47: Avg. Days to Onset | F47: Onset Pattern (illustrative)
B48: Ferrous Sulfate | C48: Constipation | D48: =COUNTIFS('ADR Patient Data'!$B$5:$B$524,B48,'ADR Patient Data'!$D$5:$D$524,C48) -> 5 | E48: =ROUND(AVERAGEIFS('ADR Patient Data'!$F$5:$F$524,'ADR Patient Data'!$B$5:$B$524,B48,'ADR Patient Data'!$D$5:$D$524,C48),1) -> 7.4 | F48: =IF(E48<=14,"Rapid & consistent — supports a link","Delayed/variable — weaker evidence") -> Rapid & consistent — supports a link | J48: =B48&" – "&C48 -> Ferrous Sulfate – Constipation
B49: Salbutamol | C49: Tremor | D49: =COUNTIFS('ADR Patient Data'!$B$5:$B$524,B49,'ADR Patient Data'!$D$5:$D$524,C49) -> 4 | E49: =ROUND(AVERAGEIFS('ADR Patient Data'!$F$5:$F$524,'ADR Patient Data'!$B$5:$B$524,B49,'ADR Patient Data'!$D$5:$D$524,C49),1) -> 7 | F49: =IF(E49<=14,"Rapid & consistent — supports a link","Delayed/variable — weaker evidence") -> Rapid & consistent — supports a link | J49: =B49&" – "&C49 -> Salbutamol – Tremor
B50: Orlistat | C50: Vomiting | D50: =COUNTIFS('ADR Patient Data'!$B$5:$B$524,B50,'ADR Patient Data'!$D$5:$D$524,C50) -> 5 | E50: =ROUND(AVERAGEIFS('ADR Patient Data'!$F$5:$F$524,'ADR Patient Data'!$B$5:$B$524,B50,'ADR Patient Data'!$D$5:$D$524,C50),1) -> 8.4 | F50: =IF(E50<=14,"Rapid & consistent — supports a link","Delayed/variable — weaker evidence") -> Rapid & consistent — supports a link | J50: =B50&" – "&C50 -> Orlistat – Vomiting
B51: Omeprazole | C51: Headache | D51: =COUNTIFS('ADR Patient Data'!$B$5:$B$524,B51,'ADR Patient Data'!$D$5:$D$524,C51) -> 4 | E51: =ROUND(AVERAGEIFS('ADR Patient Data'!$F$5:$F$524,'ADR Patient Data'!$B$5:$B$524,B51,'ADR Patient Data'!$D$5:$D$524,C51),1) -> 5.3 | F51: =IF(E51<=14,"Rapid & consistent — supports a link","Delayed/variable — weaker evidence") -> Rapid & consistent — supports a link | J51: =B51&" – "&C51 -> Omeprazole – Headache
...

Sheet Disease Prediction Data
A1: Disease Prediction Data (Diabetes Risk — Synthetic)
A2: 600 simulated patients with 6 risk factors and a diagnosis label. Rows are grouped Train (420, rows 5-424) then Test (180, rows 425-604) so the model on the next sheet can be fit on Train only and evaluated on unseen Test rows. Columns M-N are the model's predictions (computed from the fitted coefficients on the Model sheet).
A4: PatientID | B4: Age | C4: BMI | D4: Blood_Pressure | E4: Glucose_Level | F4: Family_History_Num | G4: Physical_Activity_Num | H4: Diabetes_Num | I4: Family_History | J4: Physical_Activity | K4: Diabetes_Diagnosis | L4: Split | M4: Predicted_Probability | N4: Predicted_Diagnosis
A5: DP0527 | B5: 85 | C5: 26.1 | D5: 122 | E5: 70 | F5: 0 | G5: 1 | H5: 0 | I5: No | J5: Moderate | K5: No | L5: Train | M5: ='Disease Prediction Model'!$C$9+'Disease Prediction Model'!$C$10*B5+'Disease Prediction Model'!$C$11*C5+'Disease Prediction Model'!$C$12*D5+'Disease Prediction Model'!$C$13*E5+'Disease Prediction Model'!$C$14*F5+'Disease Prediction Model'!$C$15*G5 -> 0.044969 | N5: =IF(M5>=0.5,"Yes","No") -> No
A6: DP0420 | B6: 73 | C6: 21.8 | D6: 132 | E6: 122 | F6: 0 | G6: 2 | H6: 0 | I6: No | J6: High | K6: No | L6: Train | M6: ='Disease Prediction Model'!$C$9+'Disease Prediction Model'!$C$10*B6+'Disease Prediction Model'!$C$11*C6+'Disease Prediction Model'!$C$12*D6+'Disease Prediction Model'!$C$13*E6+'Disease Prediction Model'!$C$14*F6+'Disease Prediction Model'!$C$15*G6 -> 0.377412 | N6: =IF(M6>=0.5,"Yes","No") -> No
A7: DP0100 | B7: 54 | C7: 25 | D7: 104 | E7: 96 | F7: 0 | G7: 1 | H7: 0 | I7: No | J7: Moderate | K7: No | L7: Train | M7: ='Disease Prediction Model'!$C$9+'Disease Prediction Model'!$C$10*B7+'Disease Prediction Model'!$C$11*C7+'Disease Prediction Model'!$C$12*D7+'Disease Prediction Model'!$C$13*E7+'Disease Prediction Model'!$C$14*F7+'Disease Prediction Model'!$C$15*G7 -> 0.11824 | N7: =IF(M7>=0.5,"Yes","No") -> No
A8: DP0149 | B8: 56 | C8: 30.5 | D8: 136 | E8: 93 | F8: 0 | G8: 1 | H8: 1 | I8: No | J8: Moderate | K8: Yes | L8: Train | M8: ='Disease Prediction Model'!$C$9+'Disease Prediction Model'!$C$10*B8+'Disease Prediction Model'!$C$11*C8+'Disease Prediction Model'!$C$12*D8+'Disease Prediction Model'!$C$13*E8+'Disease Prediction Model'!$C$14*F8+'Disease Prediction Model'!$C$15*G8 -> 0.273505 | N8: =IF(M8>=0.5,"Yes","No") -> No
