Workbook

Sheet Data
A1: PatientID | B1: Name | C1: Age | D1: Gender | E1: Disease | F1: Medication | G1: Dosage_mg | H1: 1 | I1: Duplicate_Flag
A2: PT0101 | B2: Abhishek Sharma | C2: 29 | D2: Male | E2: Arthritis | F2: Ibuprofen | G2: 235 | H2: 46227 | I2: Unique
A3: PT0136 | B3: Yashasvi Gupta | C3: 38 | D3: Male | E3: Diabetes | F3: Metformin | G3: 970 | H3: 46228 | I3: Unique
A4: PT0145 | B4: Virat Sharma | C4: 32 | D4: Male | E4: Flu | F4: Paracetamol | G4: 500 | H4: 46237 | I4: Unique
A5: PT0859 | B5: Mahi Saxena | C5: 54 | D5: Female | E5: Fever | F5: Paracetamol | G5: 500 | H5: 46244 | I5: Unique
A6: PT0853 | B6: Surya Yadav | C6: 43 | D6: Male | E6: Hypertension | F6: Amlodipine | G6: 5 | H6: 46246 | I6: Duplicate
A7: PT0256 | B7: Shubhman Singh | C7: 63 | D7: Male | E7: Migraine | F7: Sumatriptan | G7: 75 | H7: 46248 | I7: Unique
A8: PT0654 | B8: Jasprit Singh | C8: 44 | D8: Male | E8: Asthma | F8: Salbutamol | G8: 145 | H8: 46249 | I8: Duplicate
A9: PT0156 | B9: Anushka Sharma | C9: 26 | D9: Female | E9: Obesity | F9: Orlistat | G9: 95 | H9: 46258 | I9: Unique
A10: PT0146 | B10: Kuldeep Gupta | C10: 33 | D10: Male | E10: Diabetes | F10: Metformin | G10: 740 | H10: 46259 | I10: Unique
A11: PT0137 | B11: Rohit Nair | C11: 58 | D11: Male | E11: Arthritis | F11: Ibuprofen | G11: 320 | H11: 46260 | I11: Unique
A12: PT0035 | B12: Alok Mishra | C12: 55 | D12: Male | E12: Diabetes | F12: Metformin | G12: 755 | H12: 46261 | I12: Unique
A13: PT0214 | B13: Vinod Chauhan | C13: 50 | D13: Male | E13: Depression | F13: Sertraline | G13: 75 | H13: 46262 | I13: Unique
... A39: PT0208 | B39: Usha Joshi | C39: 27 | D39: Female | E39: Obesity | F39: Orlistat | G39: 85 | H39: 46277 | I39: Duplicate

Sheet Analysis Summary
B2: Analysis Summary
B3: Basic Anaylsis of the Data
B5: Overview
B6: Total Patients | C6: =COUNTA('[1]Cleaned Data'!A2:A39) -> 38
B7: Average Age (yrs) | C7: =AVERAGE(Data!C2:C39) -> 45.342105
B8: Median Age (yrs) | C8: =MEDIAN(Data!C2:C39) -> 46.5
B9: Youngest Patient (yrs) | C9: =MIN(Data!C2:C39) -> 10
B10: Oldest Patient (yrs) | C10: =MAX(Data!C2:C39) -> 74
B11: Average Dosage (mg) | C11: =AVERAGE(Data!G2:G39) -> 291.84211
B13: Gender Distribution
B14: Gender | C14: Patient Count | D14: % of Total
B15: Male | C15: =COUNTIF(Data!D2:D39,"Male") -> 18 | D15: =C15/$C$6 -> 0.47368421
B16: Female | C16: =COUNTIF(Data!D2:D39,"Female") -> 16 | D16: =C16/$C$6 -> 0.42105263
B17: Unknown | C17: =COUNTIF(Data!D2:D39,"Unknown") -> 4 | D17: =C17/$C$6 -> 0.10526316
B19: Most Common Diseases
B20: Disease | C20: Patient Count | D20: % of Total | E20: Avg. Age of Patients
B21: Arthritis | C21: =COUNTIF(Data!E2:E100,"Arthritis") -> 2 | D21: =C21/$C$6 -> 0.052631579 | E21: =AVERAGEIF(Data!$E$2:$E$39,B21,Data!$C$2:$C$39) -> 43.5
B22: Hypertension | C22: =COUNTIF(Data!E2:E100,"Hypertension") -> 8 | D22: =C22/$C$6 -> 0.21052632 | E22: =AVERAGEIF(Data!$E$2:$E$39,B22,Data!$C$2:$C$39) -> 53
B23: Flu | C23: =COUNTIF(Data!E2:E39,"Flu") -> 2 | D23: =C23/$C$6 -> 0.052631579 | E23: =AVERAGEIF(Data!$E$2:$E$39,B23,Data!$C$2:$C$39) -> 35.5
B24: Diabetes | C24: =COUNTIF(Data!E2:E39,"Diabetes") -> 10 | D24: =C24/$C$6 -> 0.26315789 | E24: =AVERAGEIF(Data!$E$2:$E$39,B24,Data!$C$2:$C$39) -> 45.9
B25: Fever | C25: =COUNTIF(Data!E2:E39,"Fever") -> 1 | D25: =C25/$C$6 -> 0.026315789 | E25: =AVERAGEIF(Data!$E$2:$E$39,B25,Data!$C$2:$C$39) -> 54
B26: Migraine | C26: =COUNTIF(Data!E2:E39,"Migraine") -> 4 | D26: =C26/$C$6 -> 0.10526316 | E26: =AVERAGEIF(Data!$E$2:$E$39,B26,Data!$C$2:$C$39) -> 41
B27: Asthma | C27: =COUNTIF(Data!E2:E39,"Asthma") -> 3 | D27: =C27/$C$6 -> 0.078947368 | E27: =AVERAGEIF(Data!$E$2:$E$39,B27,Data!$C$2:$C$39) -> 39
B28: Obesity | C28: =COUNTIF(Data!E2:E39,"Obesity") -> 3 | D28: =C28/$C$6 -> 0.078947368 | E28: =AVERAGEIF(Data!$E$2:$E$39,B28,Data!$C$2:$C$39) -> 35.333333
B29: Bronchitis | C29: =COUNTIF(Data!E2:E39,"Bronchitis") -> 1 | D29: =C29/$C$6 -> 0.026315789 | E29: =AVERAGEIF(Data!$E$2:$E$39,B29,Data!$C$2:$C$39) -> 48
B30: Thyroid Disorder | C30: =COUNTIF(Data!E2:E39,"Thyroid Disorder") -> 1 | D30: =C30/$C$6 -> 0.026315789 | E30: =AVERAGEIF(Data!$E$2:$E$39,B30,Data!$C$2:$C$39) -> 43
B31: Depression | C31: =COUNTIF(Data!E2:E39,"Depression") -> 2 | D31: =C31/$C$6 -> 0.052631579 | E31: =AVERAGEIF(Data!$E$2:$E$39,B31,Data!$C$2:$C$39) -> 51
B32: Anemia | C32: =COUNTIF(Data!E2:E100,"Anemia") -> 1 | D32: =C32/$C$6 -> 0.026315789 | E32: =AVERAGEIF(Data!$E$2:$E$39,B32,Data!$C$2:$C$39) -> 48
B34: Medication Usage
B35: Medication | C35: Times Prescribed | D35: Avg. Dosage(mg)
B36: Amlodipine | C36: =COUNTIF(Data!F2:F231,"Amlodipine") -> 8 | D36: =ROUND(AVERAGEIFS(Data!G2:G231,Data!F2:F231,B36),1) -> 8.8
B37: Metformin | C37: =COUNTIF(Data!F2:F231,"Metformin") -> 7 | D37: =ROUND(AVERAGEIFS(Data!G2:G231,Data!F2:F231,B37),1) -> 710.7
B38: Paracetamol | C38: =COUNTIF(Data!F2:F231,"Paracetamol") -> 2 | D38: =ROUND(AVERAGEIFS(Data!G2:G231,Data!F2:F231,B38),1) -> 500
B39: Ibuprofen | C39: =COUNTIF(Data!F2:F231,"Ibuprofen") -> 2 | D39: =ROUND(AVERAGEIFS(Data!G2:G231,Data!F2:F231,B39),1) -> 277.5
B40: Ferrous Sulfate | C40: =COUNTIF(Data!F2:F231,"Ferrous Sulfate") -> 1 | D40: =ROUND(AVERAGEIFS(Data!G2:G231,Data!F2:F231,B40),1) -> 250
B41: Orlistat | C41: =COUNTIF(Data!F2:F231,"Orlistat") -> 3 | D41: =ROUND(AVERAGEIFS(Data!G2:G231,Data!F2:F231,B41),1) -> 91.7
B42: Salbutamol | C42: =COUNTIF(Data!F2:F231,"Salbutamol") -> 3 | D42: =ROUND(AVERAGEIFS(Data!G2:G231,Data!F2:F231,B42),1) -> 158.3
B43: Sertraline | C43: =COUNTIF(Data!F2:F231,"Sertraline") -> 1 | D43: =ROUND(AVERAGEIFS(Data!G2:G231,Data!F2:F231,B43),1) -> 75
B44: Sumatriptan | C44: =COUNTIF(Data!F2:F231,"Sumatriptan") -> 3 | D44: =ROUND(AVERAGEIFS(Data!G2:G231,Data!F2:F231,B44),1) -> 60
B45: Levothyroxine | C45: =COUNTIF(Data!F2:F231,"Levothyroxine") -> 1 | D45: =ROUND(AVERAGEIFS(Data!G2:G231,Data!F2:F231,B45),1) -> 75
...

Sheet Sheet2
B2: Data Visualizations
B3: Disease distrbution, age distribition, gender ratio & medication usage - Data
B5: Disease Distribution
B6: Disease | C6: Patient Count | D6: % of Total
B7: Arthritis | C7: =COUNTIF(Data!E2:E100,"Arthritis") -> 2 | D7: 0.05
B8: Hypertension | C8: =COUNTIF(Data!E2:E100,"Hypertension") -> 8 | D8: 0.21
B9: Flu | C9: =COUNTIF(Data!E2:E100,"Flu") -> 2 | D9: 0.05
B10: Diabetes | C10: =COUNTIF(Data!E2:E100,"Diabetes") -> 10 | D10: 0.26
B11: Fever | C11: =COUNTIF(Data!E2:E100,"Fever") -> 1 | D11: 0.03
B12: Migraine | C12: =COUNTIF(Data!E2:E100,"Migraine") -> 4 | D12: 0.11
B13: Asthma | C13: =COUNTIF(Data!E2:E100,"Asthma") -> 3 | D13: 0.08
B14: Obesity | C14: =COUNTIF(Data!E2:E100,"Obesity") -> 3 | D14: 0.08
B15: Bronchitis | C15: =COUNTIF(Data!E2:E100,"Bronchitis") -> 1 | D15: 0.03
B16: Thyroid Disorder | C16: =COUNTIF(Data!E2:E100,"Thyroid disorder") -> 1 | D16: 0.03
B17: Depression | C17: =COUNTIF(Data!E2:E100,"Depression") -> 2 | D17: 0.05
B18: Anemia | C18: =COUNTIF(Data!E2:E100,"Anemia") -> 1 | D18: 0.03
B20: Age Distribution
B21: Age Range | C21: Patient Count | D21: % of Total
B22: 0-10 | C22: =COUNTIFS(Data!C2:C231,">=0",Data!C2:C231,"<=10") -> 1 | D22: =C22/'Analysis Summary'!$C$6 -> 0.026315789
B23: 11-20 | C23: =COUNTIFS(Data!C2:C39,">=11",Data!C2:C39,"<=20") -> 0 | D23: =C23/'Analysis Summary'!$C$6 -> 0
B24: 21-30 | C24: =COUNTIFS(Data!C2:C39,">=21",Data!C2:C39,"<=30") -> 4 | D24: =C24/'Analysis Summary'!$C$6 -> 0.10526316
B25: 31-40 | C25: =COUNTIFS(Data!C2:C39,">=31",Data!C2:C39,"<=40") -> 10 | D25: =C25/'Analysis Summary'!$C$6 -> 0.26315789
B26: 41-50 | C26: =COUNTIFS(Data!C2:C39,">=41",Data!C2:C39,"<=50") -> 8 | D26: =C26/'Analysis Summary'!$C$6 -> 0.21052632
B27: 51-60 | C27: =COUNTIFS(Data!C2:C39,">=51",Data!C2:C39,"<=60") -> 12 | D27: =C27/'Analysis Summary'!$C$6 -> 0.31578947
B28: 61-70 | C28: =COUNTIFS(Data!C2:C39,">=61",Data!C2:C39,"<=70") -> 2 | D28: =C28/'Analysis Summary'!$C$6 -> 0.052631579
B29: 71-80 | C29: =COUNTIFS(Data!C2:C39,">=71",Data!C2:C39,"<=80") -> 1 | D29: =C29/'Analysis Summary'!$C$6 -> 0.026315789
B30: 81-90 | C30: =COUNTIFS(Data!C2:C39,">=81",Data!C2:C39,"<=90") -> 0 | D30: =C30/'Analysis Summary'!$C$6 -> 0
B31: 91-100 | C31: =COUNTIFS(Data!C2:C39,">=91",Data!C2:C39,"<=100") -> 0 | D31: =C31/'Analysis Summary'!$C$6 -> 0
B42: Gender Ratio
B43: Gender | C43: Patient Count | D43: % of Total
B44: Male | C44: =COUNTIF(Data!D2:D39,"Male") -> 18 | D44: =C44/'Analysis Summary'!$C$6 -> 0.47368421
B45: Female | C45: =COUNTIF(Data!D2:D39,"Female") -> 16 | D45: =C45/'Analysis Summary'!$C$6 -> 0.42105263
B46: Unknown | C46: =COUNTIF(Data!D2:D39,"Unknown") -> 4 | D46: =C46/'Analysis Summary'!$C$6 -> 0.10526316
B61: Medication Usage
B62: Medication | C62: Times Prescribed | D62: % of Total
B63: Amlodipine | C63: 8 | D63: =C63/'Analysis Summary'!$C$6 -> 0.21052632
B64: Metformin | C64: 7 | D64: =C64/'Analysis Summary'!$C$6 -> 0.18421053
B65: Paracetamol | C65: 2 | D65: =C65/'Analysis Summary'!$C$6 -> 0.052631579
B66: Ibuprofen | C66: 2 | D66: =C66/'Analysis Summary'!$C$6 -> 0.052631579
B67: Ferrous Sulfate | C67: 1 | D67: =C67/'Analysis Summary'!$C$6 -> 0.026315789
...
